Workbook

Sheet REKAP
B5: REKAP BILL OF QUANTITY
B6: PEKERJAAN | E6: : | F6: MODIFIKASI PIPA ARA METER 31 & PENERIMAAN LPG
B7: LOKASI | E7: : | F7: IT CILACAP
B8: PROJECT OWNER | E8: : | F8: RPD REGION JBT
B10: NO | C10: URAIAN PEKERJAAN | J10: HARGA TOTAL
J11: (Rp)
J12: MATERIAL | K12: UPAH
B13: I | C13: =BoQ!C14 -> PEKERJAAN PERSIAPAN DAN PERALATAN KERJA | J13: =BoQ!K25 -> 0 | K13: =BoQ!L25 -> 37669562
B14: II | C14: =BoQ!C26 -> PEKERJAAN ENGINEERING DAN PROJECT MANAGEMENT | J14: =BoQ!K39 -> 0 | K14: =BoQ!L39 -> 42902460
B15: III | C15: =BoQ!C40 -> PERBAIKAN AREA METER 39 DAN MODIFIKASI PIPA AREA KILANG PERTAMINA | J15: =BoQ!K157 -> 2.9168835e+09 | K15: =BoQ!L157 -> 1.1898724e+08
B16: IV | C16: =BoQ!C159 -> PEKERJAAN PEMBUATAN PLATFORM | J16: =BoQ!K169 -> 36785959 | K16: =BoQ!L169 -> 21627778
B17: V | C17: =BoQ!C170 -> PEKERJAAN COATING | J17: =BoQ!K178 -> 1688557.7 | K17: =BoQ!L178 -> 1654265.5
B18: VI | C18: =BoQ!C179 -> PEKERJAAN TESTING DAN FINISHING | J18: =BoQ!K187 -> 0 | K18: =BoQ!L187 -> 76806843
H20: Sub Jumlah I s/d XI | J20: =SUM(J13:J19) -> 2.955358e+09 | K20: =SUM(K13:K19) -> 2.9964815e+08
H21: Jumlah Material & Jasa | K21: =K20+J20 -> 3.2550062e+09
H22: Keuntungan & Resiko Pemborong 8% | K22: =K21*8% -> 2.6040049e+08
H23: Total | K23: =ROUNDDOWN((K22+K21),-3) -> 3515406000
H24: Terbilang
C26: Exc. PPN 12%
C28: Jakarta,
C29: Diajukan : | J29: Disetujui :
C30: PT. PERTAMINA MAINTENANCE AND CONSTRUCTION | J30: PT. PERTAMINA PATRA NIAGA
C31: Project Manager | J31: Region Manager RPD JBT
C40: RIKKI ANDARFIYAN SAPUTRA | J40: M. IRSAN

Sheet BoQ
B5: BILL OF QUANTITY (BoQ) JASA & MATERIAL SUPPORT
B7: Pekerjaan | E7: : | F7: =REKAP!F6 -> MODIFIKASI PIPA ARA METER 31 & PENERIMAAN LPG
B8: Lokasi | E8: : | F8: =REKAP!F7 -> IT CILACAP
B9: Project Owner | E9: : | F9: =REKAP!F8 -> RPD REGION JBT
B11: No. | C11: URAIAN PEKERJAAN | G11: VOLUME | I11: HARGA SATUAN | K11: JUMLAH HARGA
I12: (Rp) | K12: (Rp)
I13: MATERIAL | J13: JASA | K13: MATERIAL | L13: JASA
B14: I | C14: PEKERJAAN PERSIAPAN DAN PERALATAN KERJA
B15: 1 | C15: PEKERJAAN PERSIAPAN
C16: 1.1 | D16: =link!C20 -> Mobilisasi dan Demobilisasi Pekerja dari Semarang ke FT Lomanis/IT Cilacap | G16: =analisa!P11 -> 12 | H16: =VLOOKUP($D16,link!$C$15:$R$2004,14,0) -> Trip.org | I16: =VLOOKUP($D16,link!$C$15:$R$2004,15,0) -> 0 | J16: =VLOOKUP($D16,link!$C$15:$R$2004,16,0) -> 301400 | K16: =G16*I16 -> 0 | L16: =G16*J16 -> 3616800
C17: 1.2 | D17: =link!C40 -> Mobilisasi Material dan Peralatan dengan Truck dari Semarang ke FT Lomanis/IT Cilacap | G17: =analisa!P12 -> 2 | H17: =VLOOKUP($D17,link!$C$15:$R$2004,14,0) -> Trip | I17: =VLOOKUP($D17,link!$C$15:$R$2004,15,0) -> 0 | J17: =VLOOKUP($D17,link!$C$15:$R$2004,16,0) -> 3160860 | K17: =G17*I17 -> 0 | L17: =G17*J17 -> 6321720
C18: 1.3 | D18: =link!C60 -> Mobilisasi Material dan Peralatan dengan Truck dari Luar Jateng & DIY ke FT Lomanis/IT Cilacap | G18: =analisa!P13 -> 1 | H18: =VLOOKUP($D18,link!$C$15:$R$2004,14,0) -> Trip | I18: =VLOOKUP($D18,link!$C$15:$R$2004,15,0) -> 0 | J18: =VLOOKUP($D18,link!$C$15:$R$2004,16,0) -> 5335330 | K18: =G18*I18 -> 0 | L18: =G18*J18 -> 5335330
B19: 2 | C19: PENYEDIAAN PERALATAN KERJA DAN SARFAS HSSE UNTUK KONTRUKSI
C20: 2.1 | D20: =link!C84 -> Sewa Gas Tester | G20: =analisa!P16 -> 14 | H20: =VLOOKUP($D20,link!$C$15:$R$2004,14,0) -> UD | I20: =VLOOKUP($D20,link!$C$15:$R$2004,15,0) -> 0 | J20: =VLOOKUP($D20,link!$C$15:$R$2004,16,0) -> 135680 | K20: =G20*I20 -> 0 | L20: =G20*J20 -> 1899520
C21: 2.2 | D21: =link!C93 -> Sewa Apar Powder 9 Kg | G21: =analisa!P17 -> 28 | H21: =VLOOKUP($D21,link!$C$15:$R$2004,14,0) -> UD | I21: =VLOOKUP($D21,link!$C$15:$R$2004,15,0) -> 0 | J21: =VLOOKUP($D21,link!$C$15:$R$2004,16,0) -> 4864 | K21: =G21*I21 -> 0 | L21: =G21*J21 -> 136192
B22: 3 | C22: =link!C107 -> Sewa Peralatan Pendukung Perbaikan & Perawatan
C23: 3.1 | D23: =link!C110 -> Crane 5 Ton inc BBM diluar Operator | G23: =analisa!P19 -> 4 | H23: =VLOOKUP($D23,link!$C$15:$R$2004,14,0) -> UD | I23: =VLOOKUP($D23,link!$C$15:$R$2004,15,0) -> 0 | J23: =VLOOKUP($D23,link!$C$15:$R$2004,16,0) -> 5000000 | K23: =G23*I23 -> 0 | L23: =G23*J23 -> 20000000
C24: 3.2 | D24: =link!C113 -> Sewa Scafolding tubular pipe incld. platform pijakan include Scaffolder (1,7 m x 1,7m) | G24: =analisa!P20 -> 2 | H24: =VLOOKUP($D24,link!$C$15:$R$2004,14,0) -> Set/Month | I24: =VLOOKUP($D24,link!$C$15:$R$2004,15,0) -> 0 | J24: =VLOOKUP($D24,link!$C$15:$R$2004,16,0) -> 180000 | K24: =G24*I24 -> 0 | L24: =G24*J24 -> 360000
K25: =SUM(K16:K24) -> 0 | L25: =SUM(L16:L24) -> 37669562
B26: II | C26: ='[1]analisa T.4'!$B$25 -> PEKERJAAN ENGINEERING DAN PROJECT MANAGEMENT
B27: 1 | C27: ='[1]analisa T.4'!$B$26 -> PROJECT MANAGEMENT
C28: 1.1 | D28: =link!C123 -> Safetyman | G28: =analisa!P24 -> 44 | H28: =VLOOKUP($D28,link!$C$15:$R$2004,14,0) -> MD | I28: =VLOOKUP($D28,link!$C$15:$R$2004,15,0) -> 0 | J28: =VLOOKUP($D28,link!$C$15:$R$2004,16,0) -> 487330 | K28: =G28*I28 -> 0 | L28: =G28*J28 -> 21442520
C29: 1.2 | D29: =link!C131 -> Rigger | G29: =analisa!P25 -> 14 | H29: =VLOOKUP($D29,link!$C$15:$R$2004,14,0) -> MD | I29: =VLOOKUP($D29,link!$C$15:$R$2004,15,0) -> 0 | J29: =VLOOKUP($D29,link!$C$15:$R$2004,16,0) -> 232270 | K29: =G29*I29 -> 0 | L29: =G29*J29 -> 3251780
C30: 1.3 | D30: =link!C132 -> Operator alat berat | G30: =analisa!P26 -> 14 | H30: =VLOOKUP($D30,link!$C$15:$R$2004,14,0) -> MD | I30: =VLOOKUP($D30,link!$C$15:$R$2004,15,0) -> 0 | J30: =VLOOKUP($D30,link!$C$15:$R$2004,16,0) -> 232270 | K30: =G30*I30 -> 0 | L30: =G30*J30 -> 3251780
B31: 2 | C31: =link!C139 -> Pemenuhan Dokumen Project & Engineering | G31: =analisa!P30 -> 0
C32: 2.1 | D32: =link!C140 -> Shop Drawing & Asbuilt Drawing (1 set/project) | G32: =analisa!P31 -> 1 | H32: =VLOOKUP($D32,link!$C$15:$R$2004,14,0) -> Set | I32: =VLOOKUP($D32,link!$C$15:$R$2004,15,0) -> 0 | J32: =VLOOKUP($D32,link!$C$15:$R$2004,16,0) -> 1500000 | K32: =G32*I32 -> 0 | L32: =G32*J32 -> 1500000
C33: 2.2 | D33: =link!C142 -> Spesifikasi / Approval Material (1 set/project) | G33: =analisa!P32 -> 1 | H33: =VLOOKUP($D33,link!$C$15:$R$2004,14,0) -> Set | I33: =VLOOKUP($D33,link!$C$15:$R$2004,15,0) -> 0 | J33: =VLOOKUP($D33,link!$C$15:$R$2004,16,0) -> 750000 | K33: =G33*I33 -> 0 | L33: =G33*J33 -> 750000
C34: 2.3 | D34: =link!C143 -> Laporan Teknis dan HSSE Bulanan (1 set/project) | G34: =analisa!P33 -> 1 | H34: =VLOOKUP($D34,link!$C$15:$R$2004,14,0) -> Set | I34: =VLOOKUP($D34,link!$C$15:$R$2004,15,0) -> 0 | J34: =VLOOKUP($D34,link!$C$15:$R$2004,16,0) -> 1500000 | K34: =G34*I34 -> 0 | L34: =G34*J34 -> 1500000
C35: 2.4 | D35: ='master jasa'!C143 -> WPQT include report | G35: =analisa!P34 -> 1 | H35: =VLOOKUP($D35,link!$C$15:$R$2004,14,0) -> Welder | I35: =VLOOKUP($D35,link!$C$15:$R$2004,15,0) -> 0 | J35: =VLOOKUP($D35,link!$C$15:$R$2004,16,0) -> 7785660 | K35: =G35*I35 -> 0 | L35: =G35*J35 -> 7785660
C36: 2.5 | D36: ='master jasa'!C145 -> Inspection Report | G36: =analisa!P35 -> 1 | H36: =VLOOKUP($D36,link!$C$15:$R$2004,14,0) -> Set | I36: =VLOOKUP($D36,link!$C$15:$R$2004,15,0) -> 0 | J36: =VLOOKUP($D36,link!$C$15:$R$2004,16,0) -> 750000 | K36: =G36*I36 -> 0 | L36: =G36*J36 -> 750000
C37: 2.6 | D37: ='master jasa'!C144 -> MCU personil | G37: =analisa!P36 -> 6 | H37: =VLOOKUP($D37,link!$C$15:$R$2004,14,0) -> org | I37: =VLOOKUP($D37,link!$C$15:$R$2004,15,0) -> 0 | J37: =VLOOKUP($D37,link!$C$15:$R$2004,16,0) -> 445120 | K37: =G37*I37 -> 0 | L37: =G37*J37 -> 2670720
F39: SUB-TOTAL II | K39: =SUM(K28:K37) -> 0 | L39: =SUM(L28:L37) -> 42902460
B40: III | C40: PERBAIKAN AREA METER 39 DAN MODIFIKASI PIPA AREA KILANG PERTAMINA
B41: 1 | C41: MODIFIKASI AREA PENERIMAAN (LPG)
C42: 1.1 | D42: ='master material'!C60 -> Pipa API 5L grade B Ø 10" Sch. 40 | G42: =analisa!P40 -> 9.654 | H42: =VLOOKUP($D42,link!$C$15:$R$2004,14,0) -> m | I42: =VLOOKUP($D42,link!$C$15:$R$2004,15,0) -> 2134130 | J42: =VLOOKUP($D42,link!$C$15:$R$2004,16,0) -> 0 | K42: =G42*I42 -> 20602891 | L42: =G42*J42 -> 0
C43: 1.2 | D43: ='master material'!C54 -> Pipa API 5L grade B Ø 2" Sch. 40 | G43: =analisa!P42 -> 0.116 | H43: =VLOOKUP($D43,link!$C$15:$R$2004,14,0) -> m | I43: =VLOOKUP($D43,link!$C$15:$R$2004,15,0) -> 188610 | J43: =VLOOKUP($D43,link!$C$15:$R$2004,16,0) -> 0 | K43: =G43*I43 -> 21878.76 | L43: =G43*J43 -> 0
C44: 1.3 | D44: ='master material'!C192 -> Elbow 90° schd. 40, 10" | G44: =analisa!P45 -> 2 | H44: =VLOOKUP($D44,link!$C$15:$R$2004,14,0) -> pc | I44: =VLOOKUP($D44,link!$C$15:$R$2004,15,0) -> 4113700 | J44: =VLOOKUP($D44,link!$C$15:$R$2004,16,0) -> 0 | K44: =G44*I44 -> 8227400 | L44: =G44*J44 -> 0
C45: 1.4 | D45: ='master material'!C228 -> Tee schd. 40, 10" | G45: =analisa!P46 -> 2 | H45: =VLOOKUP($D45,link!$C$15:$R$2004,14,0) -> pc | I45: =VLOOKUP($D45,link!$C$15:$R$2004,15,0) -> 5067740 | J45: =VLOOKUP($D45,link!$C$15:$R$2004,16,0) -> 0 | K45: =G45*I45 -> 10135480 | L45: =G45*J45 -> 0
C46: 1.5 | D46: ='master material'!C364 -> Weld Neck Flange #300, 10" | G46: =analisa!P47 -> 6 | H46: =VLOOKUP($D46,link!$C$15:$R$2004,14,0) -> pc | I46: =VLOOKUP($D46,link!$C$15:$R$2004,15,0) -> 3725000 | J46: =VLOOKUP($D46,link!$C$15:$R$2004,16,0) -> 0 | K46: =G46*I46 -> 22350000 | L46: =G46*J46 -> 0
C47: 1.6 | D47: ='master material'!C348 -> Weld Neck Flange #150, 10" | G47: =analisa!P48 -> 3 | H47: =VLOOKUP($D47,link!$C$15:$R$2004,14,0) -> pc | I47: =VLOOKUP($D47,link!$C$15:$R$2004,15,0) -> 2944760 | J47: =VLOOKUP($D47,link!$C$15:$R$2004,16,0) -> 0 | K47: =G47*I47 -> 8834280 | L47: =G47*J47 -> 0
...

Sheet analisa
A3: PEKERJAAN | E3: : | F3: =REKAP!F6 -> MODIFIKASI PIPA ARA METER 31 & PENERIMAAN LPG
A4: LOKASI | E4: : | F4: =REKAP!F7 -> IT CILACAP
A5: PROJECT OWNER | E5: : | F5: =REKAP!F8 -> RPD REGION JBT
A7: NO | B7: URAIAN PEKERJAAN | G7: Remaks | H7: ARITMATIKA | R7: Keterangan
H8: Panjang | I8: Lebar | J8: Tinggi | K8: Luas | L8: Ea | M8: Kg | N8: Jumlah | O8: Volume | P8: Total Volume | Q8: Satuan
A9: =BoQ!B14 -> I | B9: =BoQ!C14 -> PEKERJAAN PERSIAPAN DAN PERALATAN KERJA
A10: =BoQ!B15 -> 1 | B10: =BoQ!C15 -> PEKERJAAN PERSIAPAN
B11: =BoQ!C16 -> 1.1 | C11: =BoQ!D16 -> Mobilisasi dan Demobilisasi Pekerja dari Semarang ke FT Lomanis/IT Cilacap | G11: 12 Manpower x 2 trip | L11: 6 | N11: 2 | P11: =PRODUCT(H11:O11) -> 12 | Q11: =BoQ!H16 -> Trip.org | R11: 6 orng
B12: =BoQ!C17 -> 1.2 | C12: =BoQ!D17 -> Mobilisasi Material dan Peralatan dengan Truck dari Semarang ke FT Lomanis/IT Cilacap | G12: 2 x peralatan, 2 x material | L12: 2 | P12: =PRODUCT(H12:O12) -> 2 | Q12: =BoQ!H17 -> Trip | R12: trip ke KPI & LPG
B13: =BoQ!C18 -> 1.3 | C13: =BoQ!D18 -> Mobilisasi Material dan Peralatan dengan Truck dari Luar Jateng & DIY ke FT Lomanis/IT Cilacap | G13: 2 x pengiriman material | L13: 1 | P13: =PRODUCT(H13:O13) -> 1 | Q13: =BoQ!H18 -> Trip | R13: Ball valve dari luar kota
A14: =BoQ!B19 -> 2 | B14: =BoQ!C19 -> PENYEDIAAN PERALATAN KERJA DAN SARFAS HSSE UNTUK KONTRUKSI
B16: =BoQ!C20 -> 2.1 | C16: =BoQ!D20 -> Sewa Gas Tester | G16: 2 gas tester x 22 day | L16: 2 | N16: 7 | P16: =PRODUCT(H16:O16) -> 14 | Q16: =BoQ!H20 -> UD
B17: =BoQ!C21 -> 2.2 | C17: =BoQ!D21 -> Sewa Apar Powder 9 Kg | G17: 4 apar x 22 day | L17: 4 | N17: 7 | P17: =PRODUCT(H17:O17) -> 28 | Q17: =BoQ!H21 -> UD | R17: area KPI, crane, LPG, Gudang perlatan
A18: =BoQ!B22 -> 3 | B18: =BoQ!C22 -> Sewa Peralatan Pendukung Perbaikan & Perawatan | P18: =PRODUCT(H18:O18) -> 0 | Q18: =BoQ!H22 -> 0
B19: =BoQ!C23 -> 3.1 | C19: =BoQ!D23 -> Crane 5 Ton inc BBM diluar Operator | G19: 2 shift area penerimaan, 2 shift area meter arus | L19: =2+2 -> 4 | P19: =PRODUCT(H19:O19) -> 4 | Q19: =BoQ!H23 -> UD | R19: 2 hari KPI & 2 hari LPG
B20: =BoQ!C24 -> 3.2 | C20: =BoQ!D24 -> Sewa Scafolding tubular pipe incld. platform pijakan include Scaffolder (1,7 m x 1,7m) | P20: 2 | Q20: =BoQ!H24 -> Set/Month
A22: =BoQ!B26 -> II | B22: =BoQ!C26 -> PEKERJAAN ENGINEERING DAN PROJECT MANAGEMENT | P22: =PRODUCT(H22:O22) -> 0 | Q22: =BoQ!H26 -> 0
A23: =BoQ!B27 -> 1 | B23: =BoQ!C27 -> PROJECT MANAGEMENT | P23: =PRODUCT(H23:O23) -> 0 | Q23: =BoQ!H27 -> 0
B24: =BoQ!C28 -> 1.1 | C24: =BoQ!D28 -> Safetyman | G24: 1 safety x 22 day | L24: 2 | N24: 22 | P24: =PRODUCT(H24:O24) -> 44 | Q24: =BoQ!H28 -> MD
B25: =BoQ!C29 -> 1.2 | C25: =BoQ!D29 -> Rigger | L25: 2 | N25: 7 | P25: =PRODUCT(H25:O25) -> 14 | Q25: =BoQ!H29 -> MD | R25: area KPI & LPG
B26: =BoQ!C30 -> 1.3 | C26: =BoQ!D30 -> Operator alat berat | L26: 2 | N26: 7 | P26: =PRODUCT(H26:O26) -> 14 | Q26: =BoQ!H30 -> MD
A27: =BoQ!#REF! -> #REF! | B27: =BoQ!#REF! -> #REF! | P27: =PRODUCT(H27:O27) -> 0 | Q27: =BoQ!#REF! -> #REF!
B28: =BoQ!#REF! -> #REF! | C28: =BoQ!#REF! -> #REF! | P28: =PRODUCT(H28:O28) -> 0 | Q28: =BoQ!#REF! -> #REF!
B29: =BoQ!#REF! -> #REF! | C29: =BoQ!#REF! -> #REF! | P29: =PRODUCT(H29:O29) -> 0 | Q29: =BoQ!#REF! -> #REF!
A30: =BoQ!B31 -> 2 | B30: =BoQ!C31 -> Pemenuhan Dokumen Project & Engineering | P30: =PRODUCT(H30:O30) -> 0 | Q30: =BoQ!H31 -> 0
B31: =BoQ!C32 -> 2.1 | C31: =BoQ!D32 -> Shop Drawing & Asbuilt Drawing (1 set/project) | L31: 1 | P31: =PRODUCT(H31:O31) -> 1 | Q31: =BoQ!H32 -> Set
B32: =BoQ!C33 -> 2.2 | C32: =BoQ!D33 -> Spesifikasi / Approval Material (1 set/project) | L32: 1 | P32: =PRODUCT(H32:O32) -> 1 | Q32: =BoQ!H33 -> Set
B33: =BoQ!C34 -> 2.3 | C33: =BoQ!D34 -> Laporan Teknis dan HSSE Bulanan (1 set/project) | L33: 1 | P33: =PRODUCT(H33:O33) -> 1 | Q33: =BoQ!H34 -> Set
B34: =BoQ!C35 -> 2.4 | C34: =BoQ!D35 -> WPQT include report | L34: 1 | P34: =PRODUCT(H34:O34) -> 1 | Q34: =BoQ!H35 -> Welder
B35: =BoQ!C36 -> 2.5 | C35: =BoQ!D36 -> Inspection Report | L35: 1 | P35: =PRODUCT(H35:O35) -> 1
B36: =BoQ!C37 -> 2.6 | C36: =BoQ!D37 -> MCU personil | L36: 6 | P36: =PRODUCT(H36:O36) -> 6 | R36: 6 Orang
E37: =BoQ!F39 -> SUB-TOTAL II | P37: =PRODUCT(H37:O37) -> 0 | Q37: =BoQ!H39 -> 0
A38: =BoQ!B40 -> III | B38: =BoQ!C40 -> PERBAIKAN AREA METER 39 DAN MODIFIKASI PIPA AREA KILANG PERTAMINA | P38: =PRODUCT(H38:O38) -> 0 | Q38: =BoQ!H40 -> 0
A39: =BoQ!B41 -> 1 | B39: =BoQ!C41 -> MODIFIKASI AREA PENERIMAAN (LPG) | P39: =PRODUCT(H39:O39) -> 0 | Q39: =BoQ!H41 -> 0
B40: =BoQ!C42 -> 1.1 | C40: =BoQ!D42 -> Pipa API 5L grade B Ø 10" Sch. 40 | H40: ='perhitungan pipa 1'!E77 -> 9654 | L40: =H40/1000 -> 9.654 | P40: =H40/1000 -> 9.654 | Q40: =BoQ!H42 -> m
B42: =BoQ!C43 -> 1.2 | C42: =BoQ!D43 -> Pipa API 5L grade B Ø 2" Sch. 40 | P42: =L43+L44 -> 0.116 | Q42: =BoQ!H43 -> m
F43: Pipa PRV 1" | H43: =25+28 -> 53 | L43: =H43/1000 -> 0.053
F44: Pipa Presure gauge 1/2" | H44: =25+38 -> 63 | L44: =H44/1000 -> 0.063
B45: =BoQ!C44 -> 1.3 | C45: =BoQ!D44 -> Elbow 90° schd. 40, 10" | L45: 2 | P45: =L45 -> 2 | Q45: =BoQ!H44 -> pc
B46: =BoQ!C45 -> 1.4 | C46: =BoQ!D45 -> Tee schd. 40, 10" | L46: 2 | P46: =L46 -> 2 | Q46: =BoQ!H45 -> pc
...

Sheet perhitungan pipa 1
C3: Total dimensi (mm) | D3: Material | E3: size ( inch) | F3: rating | G3: dimensi fitting (mm) | H3: qty | I3: total dimensi (mm) | J3: pipa yg dibutuhkan (mm)
B4: LINE 1 | C4: 960 | D4: Tee equal | E4: 10 | G4: 216 | H4: 1 | I4: 216 | J4: =C4-(I4+I5+I6) -> 525 | K4: =I4+I5 -> 333.5
D5: Flange | E5: 10 | F5: 300# | G5: 117.5 | H5: 1 | I5: =G5*H5 -> 117.5
D6: Flange | E6: 10 | F6: 150# | G6: 101.5 | H6: 1 | I6: =G6*H6 -> 101.5
C8: 610 | D8: Tee equal | E8: 10 | G8: 216 | H8: 1 | I8: 216 | J8: =C8-(I8+I9) -> 276.5
D9: Flange | E9: 10 | F9: 300# | G9: 117.5 | H9: 1 | I9: =G9*H9 -> 117.5
B10: LINE 2 | C10: 960 | D10: Tee equal | E10: 10 | G10: 216 | H10: 1 | I10: 216 | J10: =C10-(I10+I11+I12) -> 525
D11: Flange | E11: 10 | F11: 300# | G11: 117.5 | H11: 1 | I11: =G11*H11 -> 117.5
D12: Flange | E12: 10 | F12: 150# | G12: 101.5 | H12: 1 | I12: =G12*H12 -> 101.5
C14: 610 | D14: Tee equal | E14: 10 | G14: 216 | H14: 1 | I14: 216 | J14: =C14-(I14+I15) -> 276.5
D15: Flange | E15: 10 | F15: 300# | G15: 117.5 | H15: 1 | I15: =G15*H15 -> 117.5
B17: LINE 3 | C17: 1430 | D17: elbow | E17: 10 | G17: 381 | H17: 1 | I17: =G17*H17 -> 381 | J17: =C17-(I17+I18) -> 931.5
D18: Flange | E18: 10 | F18: 300# | G18: 117.5 | H18: 1 | I18: =G18*H18 -> 117.5
C20: 4350 | D20: elbow | E20: 10 | G20: 381 | H20: 1 | I20: =G20*H20 -> 381 | J20: =C20-(I20+I21) -> 3851.5
D21: Flange | E21: 10 | F21: 300# | G21: 117.5 | H21: 1 | I21: =G21*H21 -> 117.5
B23: LINE 4 | C23: 1430 | D23: elbow | E23: 10 | G23: 381 | H23: 1 | I23: =G23*H23 -> 381 | J23: =C23-(I23+I24) -> 931.5
D24: Flange | E24: 10 | F24: 300# | G24: 117.5 | H24: 1 | I24: =G24*H24 -> 117.5
C26: 4350 | D26: elbow | E26: 10 | G26: 381 | H26: 1 | I26: =G26*H26 -> 381 | J26: =C26-(I26+I27) -> 3851.5
D27: Flange | E27: 10 | F27: 300# | G27: 117.5 | H27: 1 | I27: =G27*H27 -> 117.5
B29: LINE 5 | C29: 1000 | D29: elbow | E29: 10 | G29: 381 | H29: 1 | I29: =G29*H29 -> 381 | J29: =C29-(I29+I30) -> 501.5
D30: Flange | E30: 10 | F30: 300# | G30: 117.5 | H30: 1 | I30: =G30*H30 -> 117.5
C32: 1000 | D32: elbow | E32: 10 | G32: 381 | H32: 1 | I32: =G32*H32 -> 381 | J32: =C32-(I32+I33+I34+I35) -> 63
D33: Flange | E33: 10 | F33: 300# | G33: 117.5 | H33: 2 | I33: =G33*H33 -> 235
D34: red concentric | E34: 10 x 6 | G34: 178 | H34: 1 | I34: =G34*H34 -> 178
D35: tee equal | E35: 6 | G35: 143 | H35: 1 | I35: =G35*H35 -> 143
C37: 2220 | D37: elbow | E37: 6 | G37: 229 | H37: 1 | I37: =G37*H37 -> 229 | J37: =C37-(I37+I38) -> 1848
D38: tee equal | E38: 6 | G38: 143 | H38: 1 | I38: =G38*H38 -> 143
C40: 450 | D40: elbow | E40: 6 | G40: 229 | H40: 1 | I40: =G40*H40 -> 229 | J40: =C40-(I40+I41) -> 122.5
D41: Flange | E41: 6 | F41: 300# | G41: 98.5 | H41: 1 | I41: =G41*H41 -> 98.5
C43: 1050 | D43: elbow | E43: 6 | G43: 229 | H43: 1 | I43: =G43*H43 -> 229 | J43: =C43-(I43+I44) -> 678
D44: tee equal | E44: 6 | G44: 143 | H44: 1 | I44: =G44*H44 -> 143
C46: 740 | D46: elbow | E46: 6 | G46: 229 | H46: 1 | I46: =G46*H46 -> 229 | J46: =C46-(I46+I47) -> 412.5
D47: Flange | E47: 6 | F47: 300# | G47: 98.5 | H47: 1 | I47: =G47*H47 -> 98.5
B49: LINE 6 | C49: 1000 | D49: elbow | E49: 10 | G49: 381 | H49: 1 | I49: =G49*H49 -> 381 | J49: =C49-(I49+I50) -> 501.5
D50: Flange | E50: 10 | F50: 300# | G50: 117.5 | H50: 1 | I50: =G50*H50 -> 117.5
C52: 1000 | D52: elbow | E52: 10 | G52: 381 | H52: 1 | I52: =G52*H52 -> 381 | J52: =C52-(I52+I53+I54+I55) -> 63
D53: Flange | E53: 10 | F53: 300# | G53: 117.5 | H53: 2 | I53: =G53*H53 -> 235
D54: red concentric | E54: 10 x 6 | G54: 178 | H54: 1 | I54: =G54*H54 -> 178
D55: tee equal | E55: 6 | G55: 143 | H55: 1 | I55: =G55*H55 -> 143
C57: 2220 | D57: elbow | E57: 6 | G57: 229 | H57: 1 | I57: =G57*H57 -> 229 | J57: =C57-(I57+I58) -> 1848
...

Sheet perhitungan pipa
C3: Total dimensi (mm) | D3: Material | E3: size ( inch) | F3: rating | G3: dimensi fitting (mm) | H3: qty | I3: total dimensi (mm) | J3: pipa yg dibutuhkan (mm)
B4: LINE 1 | C4: 960 | D4: Tee equal | E4: 10 | G4: 216 | H4: 1 | I4: 216 | J4: =C4-(I4+I5+I6) -> 525
D5: Flange | E5: 10 | F5: 300# | G5: 117.5 | H5: 1 | I5: =G5*H5 -> 117.5
D6: Flange | E6: 10 | F6: 150# | G6: 101.5 | H6: 1 | I6: =G6*H6 -> 101.5
C8: 610 | D8: Tee equal | E8: 10 | G8: 216 | H8: 1 | I8: 216 | J8: =C8-(I8+I9) -> 276.5
D9: Flange | E9: 10 | F9: 300# | G9: 117.5 | H9: 1 | I9: =G9*H9 -> 117.5
B10: LINE 2 | C10: 960 | D10: Tee equal | E10: 10 | G10: 216 | H10: 1 | I10: 216 | J10: =C10-(I10+I11+I12) -> 525
D11: Flange | E11: 10 | F11: 300# | G11: 117.5 | H11: 1 | I11: =G11*H11 -> 117.5
D12: Flange | E12: 10 | F12: 150# | G12: 101.5 | H12: 1 | I12: =G12*H12 -> 101.5
C14: 610 | D14: Tee equal | E14: 10 | G14: 216 | H14: 1 | I14: 216 | J14: =C14-(I14+I15) -> 276.5
D15: Flange | E15: 10 | F15: 300# | G15: 117.5 | H15: 1 | I15: =G15*H15 -> 117.5
B17: LINE 3 | C17: 1430 | D17: elbow | E17: 10 | G17: 381 | H17: 1 | I17: =G17*H17 -> 381 | J17: =C17-(I17+I18) -> 931.5
D18: Flange | E18: 10 | F18: 300# | G18: 117.5 | H18: 1 | I18: =G18*H18 -> 117.5
C20: 4350 | D20: elbow | E20: 10 | G20: 381 | H20: 1 | I20: =G20*H20 -> 381 | J20: =C20-(I20+I21) -> 3851.5
D21: Flange | E21: 10 | F21: 300# | G21: 117.5 | H21: 1 | I21: =G21*H21 -> 117.5
B23: LINE 4 | C23: 1430 | D23: elbow | E23: 10 | G23: 381 | H23: 1 | I23: =G23*H23 -> 381 | J23: =C23-(I23+I24) -> 931.5
D24: Flange | E24: 10 | F24: 300# | G24: 117.5 | H24: 1 | I24: =G24*H24 -> 117.5
C26: 4350 | D26: elbow | E26: 10 | G26: 381 | H26: 1 | I26: =G26*H26 -> 381 | J26: =C26-(I26+I27) -> 3851.5
D27: Flange | E27: 10 | F27: 300# | G27: 117.5 | H27: 1 | I27: =G27*H27 -> 117.5
B29: LINE 5 | C29: 1000 | D29: elbow | E29: 10 | G29: 381 | H29: 1 | I29: =G29*H29 -> 381 | J29: =C29-(I29+I30) -> 501.5
D30: Flange | E30: 10 | F30: 300# | G30: 117.5 | H30: 1 | I30: =G30*H30 -> 117.5
C32: 1000 | D32: elbow | E32: 10 | G32: 381 | H32: 1 | I32: =G32*H32 -> 381 | J32: =C32-(I32+I33+I34+I35) -> 63
D33: Flange | E33: 10 | F33: 300# | G33: 117.5 | H33: 2 | I33: =G33*H33 -> 235
D34: red concentric | E34: 10 x 6 | G34: 178 | H34: 1 | I34: =G34*H34 -> 178
D35: tee equal | E35: 6 | G35: 143 | H35: 1 | I35: =G35*H35 -> 143
C37: 2220 | D37: elbow | E37: 6 | G37: 229 | H37: 1 | I37: =G37*H37 -> 229 | J37: =C37-(I37+I38) -> 1848
D38: tee equal | E38: 6 | G38: 143 | H38: 1 | I38: =G38*H38 -> 143
C40: 450 | D40: elbow | E40: 6 | G40: 229 | H40: 1 | I40: =G40*H40 -> 229 | J40: =C40-(I40+I41) -> 122.5
D41: Flange | E41: 6 | F41: 300# | G41: 98.5 | H41: 1 | I41: =G41*H41 -> 98.5
C43: 1050 | D43: elbow | E43: 6 | G43: 229 | H43: 1 | I43: =G43*H43 -> 229 | J43: =C43-(I43+I44) -> 678
D44: tee equal | E44: 6 | G44: 143 | H44: 1 | I44: =G44*H44 -> 143
C46: 740 | D46: elbow | E46: 6 | G46: 229 | H46: 1 | I46: =G46*H46 -> 229 | J46: =C46-(I46+I47) -> 412.5
D47: Flange | E47: 6 | F47: 300# | G47: 98.5 | H47: 1 | I47: =G47*H47 -> 98.5
B49: LINE 6 | C49: 1000 | D49: elbow | E49: 10 | G49: 381 | H49: 1 | I49: =G49*H49 -> 381 | J49: =C49-(I49+I50) -> 501.5
D50: Flange | E50: 10 | F50: 300# | G50: 117.5 | H50: 1 | I50: =G50*H50 -> 117.5
C52: 1000 | D52: elbow | E52: 10 | G52: 381 | H52: 1 | I52: =G52*H52 -> 381 | J52: =C52-(I52+I53+I54+I55) -> 63
D53: Flange | E53: 10 | F53: 300# | G53: 117.5 | H53: 2 | I53: =G53*H53 -> 235
D54: red concentric | E54: 10 x 6 | G54: 178 | H54: 1 | I54: =G54*H54 -> 178
D55: tee equal | E55: 6 | G55: 143 | H55: 1 | I55: =G55*H55 -> 143
C57: 2220 | D57: elbow | E57: 6 | G57: 229 | H57: 1 | I57: =G57*H57 -> 229 | J57: =C57-(I57+I58) -> 1848
...

Sheet TKDN A5
A6: FORM A5
A7: Pernyataan Komitmen TKDN dalam Penawaran Gabungan Barang dan Jasa
A9: Nama Penyedia Jasa | C9: : | D9: =REKAP!C30 -> PT. PERTAMINA MAINTENANCE AND CONSTRUCTION
A10: Nama Pengadaan | C10: : | D10: =BoQ!F7 -> MODIFIKASI PIPA ARA METER 31 & PENERIMAAN LPG
D11: =BoQ!F8 -> IT CILACAP
A14: A | B14: Komponen Biaya | E14: Biaya Komponen Dalam Negeri | F14: Biaya Komponen Luar Negri | G14: Biaya Total | H14: %TKDN
E15: a | F15: b | G15: c = a + b | H15: d = a/c
A16: I | B16: BARANG
A17: 1 | B17: Biaya Bahan (Material) Terpakai | E17: =G17*H17 -> 0 | F17: =G17-E17 -> 38474516 | G17: =REKAP!J20-'TKDN A5'!G18-BoQ!K114-BoQ!K51 -> 38474516 | H17: 0
A18: 2 | B18: Biaya Material Terpasang | E18: =G18*H18 -> 0 | F18: =G18-E18 -> 7.764663e+08 | G18: =SUM(BoQ!K42:K49,BoQ!K52:K91,BoQ!K93:K113,BoQ!K115:K119) -> 7.764663e+08 | H18: 0
A19: 3 | B19: Sub Jumlah | E19: =SUM(E17:E18) -> 0 | F19: =SUM(F17:F18) -> 8.1494082e+08 | G19: =SUM(G17:G18) -> 8.1494082e+08 | H19: 0
A21: II | B21: JASA
A22: 1 | B22: Biaya Tenaga Kerja dan Konsultan | E22: =G22*H22 -> 6407137.5 | F22: =G22-E22 -> 2135712.5 | G22: 8542850 | H22: 0.75
A23: 2 | B23: Biaya Alat Kerja / Fasilitas Kerja | E23: =G23*H23 -> 1092677686 | F23: =G23-E23 -> 1092677686 | G23: =SUM(BoQ!L20:L21,BoQ!L28:L30,BoQ!L32:L37,BoQ!K51,BoQ!K114) -> 2185355372 | H23: 0.5 | K23: =REKAP!K21 -> 3.2550062e+09
A24: 3 | B24: Biaya Konstruksi/Fabrikasi | E24: =G24*H24 -> 1.1580293e+08 | F24: =G24-E24 -> 38600976 | G24: =SUM(BoQ!L16:L18,BoQ!L66:L87,BoQ!L120:L155,BoQ!L161:L168) -> 1.544039e+08 | H24: =H22 -> 0.75 | K24: =G28 -> 3.2550062e+09
A25: 4 | B25: Biaya Jasa Umum | E25: =G25*H25 -> 68822417 | F25: =G25-E25 -> 22940806 | G25: =SUM(BoQ!L180:L186,BoQ!L32:L37) -> 91763223 | H25: =H24 -> 0.75 | K25: =K23-K24 -> 0.28659725
A26: 5 | B26: Sub Jumlah | E26: =SUM(E22:E25) -> 1.2837102e+09 | F26: =SUM(F22:F25) -> 1.1563552e+09 | G26: =SUM(G22:G25) -> 2.4400653e+09 | H26: =(E26/G26)*100% -> 0.52609663
A28: III | B28: Jumlah Biaya Barang + Jasa | E28: =E26+E19 -> 1.2837102e+09 | F28: =F26+F19 -> 1.971296e+09 | G28: =G19+G26 -> 3.2550062e+09 | H28: =(E28/G28)*100% -> 0.39438026
A30: B | B30: Komponen Bukan Biaya ( Non Cost Component) | G30: =G28*8% -> 2.6040049e+08
A32: C | B32: Jumlah Nilai Penawaran (Total Quoted Price) | G32: =ROUNDDOWN((G28+G30),-3) -> 3515406000
E35: =REKAP!C28 -> Jakarta,
E36: =[2]REKAP!B30 -> Diajukan :
E37: =REKAP!C30 -> PT. PERTAMINA MAINTENANCE AND CONSTRUCTION
E45: =REKAP!C40 -> RIKKI ANDARFIYAN SAPUTRA
E46: =REKAP!C31 -> Project Manager

Sheet TKDN A6
A5: DETAIL FORM A6
A6: Peta Jalur (Roadmap) Komitmen TKDN oleh Penyedia Barang/Jasa
A8: Nama Penyedia Jasa | D8: : | E8: ='TKDN A5'!D9 -> PT. PERTAMINA MAINTENANCE AND CONSTRUCTION
A9: Nama Pengadaan | D9: : | E9: ='TKDN A5'!D10 -> MODIFIKASI PIPA ARA METER 31 & PENERIMAAN LPG
E10: ='TKDN A5'!D11 -> IT CILACAP
A12: Periode Pelaksanaan Kontrak | E12: Bulan ke | L12: Akhir Masa Kontrak (n)
E14: 6 | F14: 12 | G14: 18 | H14: 24 | I14: 30 | J14: dst | K14: n-6
A15: Komitmen % TKDN | L15: ='TKDN A5'!H28 -> 0.39438026
A16: Realisasi % TKDN
F19: ='[2]TKDN A5'!E36 -> Diajukan :
F20: ='TKDN A5'!E37 -> PT. PERTAMINA MAINTENANCE AND CONSTRUCTION
F28: ='TKDN A5'!E45 -> RIKKI ANDARFIYAN SAPUTRA
F29: ='TKDN A5'!E46 -> Project Manager

Sheet KURVA S
A5: JUDUL PEKERJAAN | F5: : | G5: =BoQ!F7 -> MODIFIKASI PIPA ARA METER 31 & PENERIMAAN LPG
A6: LOKASI | F6: : | G6: =BoQ!F8 -> IT CILACAP
A7: NO & TGL SPB
A8: JANGKA WAKTU | F8: : | G8: 90 (Sembilan Puluh) HARI KALENDER
A10: NO | B10: URAIAN PEKERJAAN | H10: HARGA SATUAN | I10: BOBOT % | J10: KET. | K10: BULAN - 1 | O10: BULAN - 2 | S10: BULAN - 3 | W10: VALUE SCALE
K11: MINGGU KE - | O11: MINGGU KE - | S11: MINGGU KE -
K12: 1 | L12: 2 | M12: 3 | N12: 4 | O12: 5 | P12: 6 | Q12: 7 | R12: 8 | S12: 9 | T12: 10 | U12: 11 | V12: 12
K13: 08 Okt - 10 Okt | L13: 11 Okt - 17 Okt | M13: 18 Okt - 24 Okt | N13: 25 Okt - 31 Okt | O13: 08 Nov - 14 Nov | P13: 15 Nov - 21 Nov | Q13: 22 Nov - 28 Nov | R13: 29 Nov - 05 Des | S13: 06 Des - 12 Des | T13: 13 Des - 19 Des | U13: 20 Des - 26 Des
A15: =BoQ!B14 -> I | B15: =BoQ!C14 -> PEKERJAAN PERSIAPAN DAN PERALATAN KERJA
A16: 1 | B16: =BoQ!C15 -> PEKERJAAN PERSIAPAN
B17: =BoQ!C16 -> 1.1 | C17: =BoQ!D16 -> Mobilisasi dan Demobilisasi Pekerja dari Semarang ke FT Lomanis/IT Cilacap | H17: =SUM(BoQ!K16:L16) -> 3616800 | I17: =H17/H$178% -> 0.111115 | J17: RENCANA | O17: =I17/7 -> 0.015873571 | P17: =O17 -> 0.015873571 | Q17: =P17 -> 0.015873571 | R17: =Q17 -> 0.015873571 | S17: =R17 -> 0.015873571 | T17: =S17 -> 0.015873571 | U17: =T17 -> 0.015873571
B18: =BoQ!C17 -> 1.2 | C18: =BoQ!D17 -> Mobilisasi Material dan Peralatan dengan Truck dari Semarang ke FT Lomanis/IT Cilacap | H18: =SUM(BoQ!K17:L17) -> 6321720 | I18: =H18/H$178% -> 0.1942153 | J18: RENCANA | O18: ='KURVA S'!I18/2 -> 0.09710765 | U18: =O18 -> 0.09710765
B19: =BoQ!C18 -> 1.3 | C19: =BoQ!D18 -> Mobilisasi Material dan Peralatan dengan Truck dari Luar Jateng & DIY ke FT Lomanis/IT Cilacap | H19: =SUM(BoQ!K18:L18) -> 5335330 | I19: =H19/H$178% -> 0.16391152 | J19: RENCANA | O19: =I19/3 -> 0.054637172
A20: 2 | B20: =BoQ!C19 -> PENYEDIAAN PERALATAN KERJA DAN SARFAS HSSE UNTUK KONTRUKSI
B21: =BoQ!C20 -> 2.1 | C21: =BoQ!D20 -> Sewa Gas Tester | H21: =SUM(BoQ!K20:L20) -> 1899520 | I21: =H21/H$178% -> 0.058356879 | J21: RENCANA | P21: =I21/5 -> 0.011671376 | Q21: =P21 -> 0.011671376 | R21: =Q21 -> 0.011671376 | S21: =Q21 -> 0.011671376 | T21: =S21 -> 0.011671376
B22: =BoQ!C21 -> 2.2 | C22: =BoQ!D21 -> Sewa Apar Powder 9 Kg | H22: =SUM(BoQ!K21:L21) -> 136192 | I22: =H22/H$178% -> 0.0041840781 | J22: RENCANA | O22: =I22/7 -> 0.00059772544 | P22: =O22 -> 0.00059772544 | Q22: =P22 -> 0.00059772544 | R22: =Q22 -> 0.00059772544 | S22: =R22 -> 0.00059772544 | T22: =S22 -> 0.00059772544 | U22: =T22 -> 0.00059772544
A23: 3 | B23: =BoQ!C22 -> Sewa Peralatan Pendukung Perbaikan & Perawatan
B24: =BoQ!C23 -> 3.1 | C24: =BoQ!D23 -> Crane 5 Ton inc BBM diluar Operator | H24: =SUM(BoQ!K23:L23) -> 20000000 | I24: =H24/H$178% -> 0.61443816 | J24: RENCANA | Q24: =I24/2 -> 0.30721908 | T24: =Q24 -> 0.30721908
B25: =BoQ!C24 -> 3.2 | C25: =BoQ!D24 -> Sewa Scafolding tubular pipe incld. platform pijakan include Scaffolder (1,7 m x 1,7m) | H25: =SUM(BoQ!K24:L24) -> 360000 | I25: =H25/H$178% -> 0.011059887 | J25: RENCANA | Q25: =I25/2 -> 0.0055299434 | T25: =Q25 -> 0.0055299434
A27: =BoQ!B26 -> II | B27: =BoQ!C26 -> PEKERJAAN ENGINEERING DAN PROJECT MANAGEMENT
A28: =BoQ!B27 -> 1 | B28: =BoQ!C27 -> PROJECT MANAGEMENT
B29: =BoQ!C28 -> 1.1 | C29: =BoQ!D28 -> Safetyman | H29: =SUM(BoQ!K28:L28) -> 21442520 | I29: =H29/H$178% -> 0.65875513 | J29: RENCANA | O29: =I29/7 -> 0.094107875 | P29: =O29 -> 0.094107875 | Q29: =P29 -> 0.094107875 | R29: =Q29 -> 0.094107875 | S29: =R29 -> 0.094107875 | T29: =S29 -> 0.094107875 | U29: =T29 -> 0.094107875
B30: =BoQ!C29 -> 1.2 | C30: =BoQ!D29 -> Rigger | H30: =SUM(BoQ!K29:L29) -> 3251780 | I30: =H30/H$178% -> 0.099900886 | J30: RENCANA | Q30: =I30/2 -> 0.049950443 | T30: =Q30 -> 0.049950443
B31: =BoQ!C30 -> 1.3 | C31: =BoQ!D30 -> Operator alat berat | H31: =SUM(BoQ!K30:L30) -> 3251780 | I31: =H31/H$178% -> 0.099900886 | J31: RENCANA | Q31: =I31/2 -> 0.049950443 | T31: =Q31 -> 0.049950443
A32: =BoQ!B31 -> 2 | B32: =BoQ!C31 -> Pemenuhan Dokumen Project & Engineering | H32: =SUM(BoQ!K31:L31) -> 0
B33: =BoQ!C32 -> 2.1 | C33: =BoQ!D32 -> Shop Drawing & Asbuilt Drawing (1 set/project) | H33: =SUM(BoQ!K32:L32) -> 1500000 | I33: =H33/H$178% -> 0.046082862 | J33: RENCANA | K33: =I33/4 -> 0.011520716 | L33: =K33 -> 0.011520716 | M33: =L33 -> 0.011520716 | N33: =M33 -> 0.011520716
B34: =BoQ!C33 -> 2.2 | C34: =BoQ!D33 -> Spesifikasi / Approval Material (1 set/project) | H34: =SUM(BoQ!K33:L33) -> 750000 | I34: =H34/H$178% -> 0.023041431 | J34: RENCANA | L34: =I34/3 -> 0.007680477 | M34: =L34 -> 0.007680477 | N34: =M34 -> 0.007680477
B35: =BoQ!C34 -> 2.3 | C35: =BoQ!D34 -> Laporan Teknis dan HSSE Bulanan (1 set/project) | H35: =SUM(BoQ!K34:L34) -> 1500000 | I35: =H35/H$178% -> 0.046082862 | J35: RENCANA | N35: =I35/3 -> 0.015360954 | R35: =N35 -> 0.015360954 | U35: =R35 -> 0.015360954
B36: =BoQ!C35 -> 2.4 | C36: =BoQ!D35 -> WPQT include report | H36: =SUM(BoQ!K35:L35) -> 7785660 | I36: =H36/H$178% -> 0.23919033 | J36: RENCANA | P36: =I36 -> 0.23919033
B37: =BoQ!C36 -> 2.5 | C37: =BoQ!D36 -> Inspection Report | H37: =SUM(BoQ!K36:L36) -> 750000 | I37: =H37/H$178% -> 0.023041431 | J37: RENCANA | U37: =I37 -> 0.023041431
B38: =BoQ!C37 -> 2.6 | C38: =BoQ!D37 -> MCU personil | H38: =SUM(BoQ!K37:L37) -> 2670720 | I38: =H38/H$178% -> 0.082049614 | J38: RENCANA | L38: =I38/3 -> 0.027349871 | M38: =L38 -> 0.027349871 | N38: =M38 -> 0.027349871
A39: =BoQ!B40 -> III | B39: =BoQ!C40 -> PERBAIKAN AREA METER 39 DAN MODIFIKASI PIPA AREA KILANG PERTAMINA
A40: =BoQ!B41 -> 1 | B40: =BoQ!C41 -> MODIFIKASI AREA PENERIMAAN (LPG)
B41: =BoQ!C42 -> 1.1 | C41: =BoQ!D42 -> Pipa API 5L grade B Ø 10" Sch. 40 | H41: =SUM(BoQ!K42:L42) -> 20602891 | I41: =H41/H$178% -> 0.63296012 | J41: RENCANA | N41: =I41 -> 0.63296012
B42: =BoQ!C43 -> 1.2 | C42: =BoQ!D43 -> Pipa API 5L grade B Ø 2" Sch. 40 | H42: =SUM(BoQ!K43:L43) -> 21878.76 | I42: =H42/H$178% -> 0.00067215725 | J42: RENCANA | N42: =I42 -> 0.00067215725
B43: =BoQ!C44 -> 1.3 | C43: =BoQ!D44 -> Elbow 90° schd. 40, 10" | H43: =SUM(BoQ!K44:L44) -> 8227400 | I43: =H43/H$178% -> 0.25276143 | J43: RENCANA | O43: =I43 -> 0.25276143
B44: =BoQ!C45 -> 1.4 | C44: =BoQ!D45 -> Tee schd. 40, 10" | H44: =SUM(BoQ!K45:L45) -> 10135480 | I44: =H44/H$178% -> 0.31138128 | J44: RENCANA | O44: =I44 -> 0.31138128
B45: =BoQ!C46 -> 1.5 | C45: =BoQ!D46 -> Weld Neck Flange #300, 10" | H45: =SUM(BoQ!K46:L46) -> 22350000 | I45: =H45/H$178% -> 0.68663464 | J45: RENCANA | O45: =I45 -> 0.68663464
B46: =BoQ!C47 -> 1.6 | C46: =BoQ!D47 -> Weld Neck Flange #150, 10" | H46: =SUM(BoQ!K47:L47) -> 8834280 | I46: =H46/H$178% -> 0.27140594 | J46: RENCANA | O46: =I46 -> 0.27140594
B47: =BoQ!C48 -> 1.7 | C47: =BoQ!D48 -> Weld Neck Flange #150, 1" | H47: =SUM(BoQ!K48:L48) -> 464660 | I47: =H47/H$178% -> 0.014275242 | J47: RENCANA | O47: =I47 -> 0.014275242
...

Sheet link
B4: BILL OF QUANTITY (BoQ) JASA & MATERIAL SUPPORT
B6: Pekerjaan | F6: : | G6: Kontrak Payung Cleaning, Coating Dan Perbaikan Tangki Timbun dan Perpipaan Regional JBT
B7: Lokasi | F7: : | G7: All
B8: Mata Anggaran | F8: : | G8: ABO
B9: Project Owner | F9: : | G9: S&D Regional JBT
B11: No. | C11: URAIAN PEKERJAAN | O11: VOLUME | Q11: HARGA SATUAN (Rp) | S11: JUMLAH HARGA (Rp)
Q12: MATERIAL | R12: JASA | S12: MATERIAL | T12: JASA
B13: A. | C13: JASA
B14: I | C14: PEKERJAAN PERSIAPAN, ENGINEERING DAN PROJECT MANAGEMENT
B15: 1 | C15: Direksi Kit Container Ukuran 20 ft | O15: 1 | P15: Month | Q15: ='master jasa'!Q13 -> 0 | R15: ='master jasa'!R13 -> 11324600 | T15: =R15*O15 -> 11324600
B16: 2 | C16: Direksi Kit Bangunan Kelas 3 | O16: 1 | P16: m2 | Q16: ='master jasa'!Q14 -> 0 | R16: ='master jasa'!R14 -> 1761180 | T16: =R16*O16 -> 1761180
B17: 3 | C17: Sewa Tempat Tinggal Pekerja di Lokasi | J17: (sesuai durasi pekerjaan) | O17: 1 | P17: unit/month | Q17: ='master jasa'!Q15 -> 0 | R17: ='master jasa'!R15 -> 2418000 | T17: =R17*O17 -> 2418000
B18: 4 | C18: Sewa Mobil Operasional Area Jateng & DIY termasuk O&M | O18: 1 | P18: unit/month | Q18: ='master jasa'!Q16 -> 0 | R18: ='master jasa'!R16 -> 15327770 | T18: =R18*O18 -> 15327770
B19: 5 | C19: Mobilisasi dan Demobilisasi Pekerja dari Semarang ke FT Tegal | O19: 1 | P19: Trip.org | Q19: ='master jasa'!Q17 -> 0 | R19: ='master jasa'!R17 -> 207400 | T19: =R19*O19 -> 207400
B20: 6 | C20: Mobilisasi dan Demobilisasi Pekerja dari Semarang ke FT Lomanis/IT Cilacap | O20: 1 | P20: Trip.org | Q20: ='master jasa'!Q18 -> 0 | R20: ='master jasa'!R18 -> 301400 | T20: =R20*O20 -> 301400
B21: 7 | C21: Mobilisasi dan Demobilisasi Pekerja dari Semarang ke FT Maos | O21: 1 | P21: Trip.org | Q21: ='master jasa'!Q19 -> 0 | R21: ='master jasa'!R19 -> 287580 | T21: =R21*O21 -> 287580
B22: 8 | C22: Mobilisasi dan Demobilisasi Pekerja dari Semarang ke FT Lomanis - Booster Kutowinangun | O22: 1 | P22: Trip.org | Q22: ='master jasa'!Q20 -> 0 | R22: ='master jasa'!R20 -> 301400 | T22: =R22*O22 -> 301400
B23: 9 | C23: Mobilisasi dan Demobilisasi Pekerja dari Semarang ke AT Yogyakarta International Airport | O23: 1 | P23: Trip.org | Q23: ='master jasa'!Q21 -> 0 | R23: ='master jasa'!R21 -> 259720 | T23: =R23*O23 -> 259720
B24: 10 | C24: Mobilisasi dan Demobilisasi Pekerja dari Semarang ke FT Rewulu | O24: 1 | P24: Trip.org | Q24: ='master jasa'!Q22 -> 0 | R24: ='master jasa'!R22 -> 259720 | T24: =R24*O24 -> 259720
B25: 11 | C25: Mobilisasi dan Demobilisasi Pekerja dari Semarang ke AT Adi Sucipto | O25: 1 | P25: Trip.org | Q25: ='master jasa'!Q23 -> 0 | R25: ='master jasa'!R23 -> 259720 | T25: =R25*O25 -> 259720
B26: 12 | C26: Mobilisasi dan Demobilisasi Pekerja dari Semarang ke AT Adi Soemarmo | O26: 1 | P26: Trip.org | Q26: ='master jasa'!Q24 -> 0 | R26: ='master jasa'!R24 -> 242060 | T26: =R26*O26 -> 242060
B27: 13 | C27: Mobilisasi dan Demobilisasi Pekerja dari Semarang ke FT Boyolali | O27: 1 | P27: Trip.org | Q27: ='master jasa'!Q25 -> 0 | R27: ='master jasa'!R25 -> 242060 | T27: =R27*O27 -> 242060
B28: 14 | C28: Mobilisasi dan Demobilisasi Pekerja dari Semarang ke FT Boyolali - Cepu | O28: 1 | P28: Trip.org | Q28: ='master jasa'!Q26 -> 0 | R28: ='master jasa'!R26 -> 296470 | T28: =R28*O28 -> 296470
B29: 15 | C29: Mobilisasi Material dan Peralatan dari Semarang ke FT Tegal | O29: 1 | P29: kg | Q29: ='master jasa'!Q27 -> 0 | R29: ='master jasa'!R27 -> 537.07 | T29: =R29*O29 -> 537.07
... B78: 64 | C78: Mobilisasi Material dan Peralatan dengan Trailer dari Luar Jateng & DIY ke FT Boyolali-Cepu | O78: 1 | P78: Trip | Q78: ='master jasa'!Q76 -> 0 | R78: ='master jasa'!R76 -> 8369190 | T78: =R78*O78 -> 8369190
B79: 65 | C79: Penyediaan Peralatan Kerja dan Sarfas HSSE untuk Kontruksi : | Q79: ='master jasa'!Q77 -> 0 | R79: ='master jasa'!R77 -> 0
B80: a. | C80: Sewa Blower Explossion Proof Portable | O80: 1 | P80: UD | Q80: ='master jasa'!Q78 -> 0 | R80: ='master jasa'!R78 -> 22747.06 | T80: =R80*O80 -> 22747.06
B81: b. | C81: Sewa Pompa Air Mesin Diesel 5 kW | O81: 1 | P81: UD | Q81: ='master jasa'!Q79 -> 0 | R81: ='master jasa'!R79 -> 669010 | T81: =R81*O81 -> 669010
B82: c. | C82: Sewa Genset 10 kVA, include BBM, Pelumas, Operator dan Maintenance | O82: 1 | P82: UD | Q82: ='master jasa'!Q80 -> 0 | R82: ='master jasa'!R80 -> 2292980 | T82: =R82*O82 -> 2292980
B83: d. | C83: Sewa Genset 5 kVA, include BBM, Pelumas, Operator dan Maintenance | O83: 1 | P83: UD | Q83: ='master jasa'!Q81 -> 0 | R83: ='master jasa'!R81 -> 1966320 | T83: =R83*O83 -> 1966320
B84: e. | C84: Sewa Gas Tester | O84: 1 | P84: UD | Q84: ='master jasa'!Q82 -> 0 | R84: ='master jasa'!R82 -> 135680 | T84: =R84*O84 -> 135680
B85: f. | C85: Sewa Lampu Penerangan (Explosion Proof Lamp) min. 100 Watt | O85: 1 | P85: UD | Q85: ='master jasa'!Q83 -> 0 | R85: ='master jasa'!R83 -> 38650 | T85: =R85*O85 -> 38650
B86: g. | C86: Sewa Welding Habitat | O86: 1 | P86: unit | Q86: ='master jasa'!Q84 -> 0 | R86: ='master jasa'!R84 -> 5558430 | T86: =R86*O86 -> 5558430
B87: h. | C87: Pembuatan Tirai Air include air tawar inc peralatan (Selang & tools) | O87: 1 | P87: m2 | Q87: ='master jasa'!Q85 -> 0 | R87: ='master jasa'!R85 -> 506100 | T87: =R87*O87 -> 506100
B88: i. | C88: Sewa Selang (Composite Hose) size 2,5" x9m | O88: 1 | P88: UD | Q88: ='master jasa'!Q86 -> 0 | R88: ='master jasa'!R86 -> 43870 | T88: =R88*O88 -> 43870
B89: j. | C89: Sewa Selang (Composite Hose) size 3" x9m | O89: 1 | P89: UD | Q89: ='master jasa'!Q87 -> 0 | R89: ='master jasa'!R87 -> 52640 | T89: =R89*O89 -> 52640
B90: k. | C90: Sewa Selang (Composite Hose) size 4" x9m | O90: 1 | P90: UD | Q90: ='master jasa'!Q88 -> 0 | R90: ='master jasa'!R88 -> 61420 | T90: =R90*O90 -> 61420
B91: l. | C91: Sewa Wind Barrier untuk Outer Roof & Shell Tangki | O91: 1 | P91: m2 | Q91: ='master jasa'!Q89 -> 0 | R91: ='master jasa'!R89 -> 58210 | T91: =R91*O91 -> 58210
... B95: p. | C95: Sewa Kompresor | O95: 1 | P95: UD | Q95: ='master jasa'!Q93 -> 0 | R95: ='master jasa'!R93 -> 326920 | T95: =R95*O95 -> 326920
Q96: ='master jasa'!Q94 -> 0 | R96: ='master jasa'!R94 -> 0
...

Sheet master jasa
B3: BILL OF QUANTITY (BoQ) JASA & MATERIAL SUPPORT
B5: Pekerjaan | F5: : | G5: Kontrak Payung Cleaning, Coating Dan Perbaikan Tangki Timbun dan Perpipaan Regional JBT
B6: Lokasi | F6: : | G6: All
B7: Mata Anggaran | F7: : | G7: ABO
B8: Project Owner | F8: : | G8: S&D Regional JBT
B10: No. | C10: URAIAN PEKERJAAN | O10: VOLUME | Q10: HARGA SATUAN (Rp) | S10: JUMLAH HARGA (Rp)
Q11: MATERIAL | R11: JASA | S11: MATERIAL | T11: JASA
B12: I | C12: PEKERJAAN PERSIAPAN, ENGINEERING DAN PROJECT MANAGEMENT
B13: 1 | C13: Direksi Kit Container Ukuran 20 ft | O13: 1 | P13: Month | R13: 11324600 | T13: =R13*O13 -> 11324600
B14: 2 | C14: Direksi Kit Bangunan Kelas 3 | O14: 1 | P14: m2 | R14: 1761180 | T14: =R14*O14 -> 1761180
B15: 3 | C15: Sewa Tempat Tinggal Pekerja di Lokasi | J15: (sesuai durasi pekerjaan) | O15: 1 | P15: unit/month | R15: 2418000 | T15: =R15*O15 -> 2418000
B16: 4 | C16: Sewa Mobil Operasional Area Jateng & DIY termasuk O&M | O16: 1 | P16: unit/month | R16: 15327770 | T16: =R16*O16 -> 15327770
B17: 5 | C17: Mobilisasi dan Demobilisasi Pekerja dari Semarang ke FT Tegal | O17: 1 | P17: Trip.org | R17: 207400 | T17: =R17*O17 -> 207400
B18: 6 | C18: Mobilisasi dan Demobilisasi Pekerja dari Semarang ke FT Lomanis/IT Cilacap | O18: 1 | P18: Trip.org | R18: 301400 | T18: =R18*O18 -> 301400
B19: 7 | C19: Mobilisasi dan Demobilisasi Pekerja dari Semarang ke FT Maos | O19: 1 | P19: Trip.org | R19: 287580 | T19: =R19*O19 -> 287580
B20: 8 | C20: Mobilisasi dan Demobilisasi Pekerja dari Semarang ke FT Lomanis - Booster Kutowinangun | O20: 1 | P20: Trip.org | R20: 301400 | T20: =R20*O20 -> 301400
B21: 9 | C21: Mobilisasi dan Demobilisasi Pekerja dari Semarang ke AT Yogyakarta International Airport | O21: 1 | P21: Trip.org | R21: 259720 | T21: =R21*O21 -> 259720
B22: 10 | C22: Mobilisasi dan Demobilisasi Pekerja dari Semarang ke FT Rewulu | O22: 1 | P22: Trip.org | R22: 259720 | T22: =R22*O22 -> 259720
B23: 11 | C23: Mobilisasi dan Demobilisasi Pekerja dari Semarang ke AT Adi Sucipto | O23: 1 | P23: Trip.org | R23: 259720 | T23: =R23*O23 -> 259720
B24: 12 | C24: Mobilisasi dan Demobilisasi Pekerja dari Semarang ke AT Adi Soemarmo | O24: 1 | P24: Trip.org | R24: 242060 | T24: =R24*O24 -> 242060
B25: 13 | C25: Mobilisasi dan Demobilisasi Pekerja dari Semarang ke FT Boyolali | O25: 1 | P25: Trip.org | R25: 242060 | T25: =R25*O25 -> 242060
B26: 14 | C26: Mobilisasi dan Demobilisasi Pekerja dari Semarang ke FT Boyolali - Cepu | O26: 1 | P26: Trip.org | R26: 296470 | T26: =R26*O26 -> 296470
B27: 15 | C27: Mobilisasi Material dan Peralatan dari Semarang ke FT Tegal | O27: 1 | P27: kg | R27: 537.07 | T27: =R27*O27 -> 537.07
... B76: 64 | C76: Mobilisasi Material dan Peralatan dengan Trailer dari Luar Jateng & DIY ke FT Boyolali-Cepu | O76: 1 | P76: Trip | R76: 8369190 | T76: =R76*O76 -> 8369190
B77: 65 | C77: Penyediaan Peralatan Kerja dan Sarfas HSSE untuk Kontruksi :
B78: a. | C78: Sewa Blower Explossion Proof Portable | O78: 1 | P78: UD | R78: 22747.06 | T78: =R78*O78 -> 22747.06
B79: b. | C79: Sewa Pompa Air Mesin Diesel 5 kW | O79: 1 | P79: UD | R79: 669010 | T79: =R79*O79 -> 669010
B80: c. | C80: Sewa Genset 10 kVA, include BBM, Pelumas, Operator dan Maintenance | O80: 1 | P80: UD | R80: 2292980 | T80: =R80*O80 -> 2292980
B81: d. | C81: Sewa Genset 5 kVA, include BBM, Pelumas, Operator dan Maintenance | O81: 1 | P81: UD | R81: 1966320 | T81: =R81*O81 -> 1966320
B82: e. | C82: Sewa Gas Tester | O82: 1 | P82: UD | R82: 135680 | T82: =R82*O82 -> 135680
B83: f. | C83: Sewa Lampu Penerangan (Explosion Proof Lamp) min. 100 Watt | O83: 1 | P83: UD | R83: 38650 | T83: =R83*O83 -> 38650
B84: g. | C84: Sewa Welding Habitat | O84: 1 | P84: unit | R84: 5558430 | T84: =R84*O84 -> 5558430
B85: h. | C85: Pembuatan Tirai Air include air tawar inc peralatan (Selang & tools) | O85: 1 | P85: m2 | R85: 506100 | T85: =R85*O85 -> 506100
B86: i. | C86: Sewa Selang (Composite Hose) size 2,5" x9m | O86: 1 | P86: UD | R86: 43870 | T86: =R86*O86 -> 43870
B87: j. | C87: Sewa Selang (Composite Hose) size 3" x9m | O87: 1 | P87: UD | R87: 52640 | T87: =R87*O87 -> 52640
B88: k. | C88: Sewa Selang (Composite Hose) size 4" x9m | O88: 1 | P88: UD | R88: 61420 | T88: =R88*O88 -> 61420
B89: l. | C89: Sewa Wind Barrier untuk Outer Roof & Shell Tangki | O89: 1 | P89: m2 | R89: 58210 | T89: =R89*O89 -> 58210
... B93: p. | C93: Sewa Kompresor | O93: 1 | P93: UD | R93: 326920 | T93: =R93*O93 -> 326920
B95: 66 | C95: Sewa Peralatan Purging N2
B96: a. | C96: Isotank 14 Ton atau Setara, 1 Unit | O96: 1 | P96: UD | R96: 3200000 | T96: =R96*O96 -> 3200000
...

Sheet master material
B3: BILL OF QUANTITY (BoQ) MATERIAL UTAMA
B5: Pekerjaan | F5: : | G5: Kontrak Payung Cleaning, Coating Dan Perbaikan Tangki Timbun dan Perpipaan Regional JBT
B6: Lokasi | F6: : | G6: All
B7: Mata Anggaran | F7: : | G7: ABO
B8: Project Owner | F8: : | G8: S&D Regional JBT
B10: No. | C10: URAIAN PEKERJAAN | H10: VOLUME | J10: HARGA SATUAN (Rp) | L10: JUMLAH HARGA (Rp)
J11: MATERIAL | K11: JASA | L11: MATERIAL | M11: JASA
B12: I | C12: STEEL PLATE
B13: 1 | C13: Steel Plate ASTM A283 Gr.C
B14: 1.1 | C14: Plate 6 mm ASTM A283 Gr.C | H14: 1 | I14: Kg | J14: 14260 | L14: =H14*J14 -> 14260
B15: 1.2 | C15: Plate 8 mm ASTM A283 Gr.C | H15: 1 | I15: Kg | J15: 12835 | L15: =H15*J15 -> 12835
B16: 1.3 | C16: Plate 10 mm ASTM A283 Gr.C | H16: 1 | I16: Kg | J16: 12770 | L16: =H16*J16 -> 12770
B17: 1.4 | C17: Plate 12 mm ASTM A283 Gr.C | H17: 1 | I17: Kg | J17: 12737 | L17: =H17*J17 -> 12737
B18: 1.5 | C18: Plate 14 mm ASTM A283 Gr.C | H18: 1 | I18: Kg | J18: 12737 | L18: =H18*J18 -> 12737
B19: 1.6 | C19: Plate 16 mm ASTM A283 Gr.C | H19: 1 | I19: Kg | J19: 12737 | L19: =H19*J19 -> 12737
B20: 1.7 | C20: Plate 18 mm ASTM A283 Gr.C | H20: 1 | I20: Kg | J20: 12737 | L20: =H20*J20 -> 12737
B21: 1.8 | C21: Plate 20 mm ASTM A283 Gr.C | H21: 1 | I21: Kg | J21: 12737 | L21: =H21*J21 -> 12737
B22: 1.9 | C22: Plate 22 mm ASTM A283 Gr.C | H22: 1 | I22: Kg | J22: 13361 | L22: =H22*J22 -> 13361
B23: 1.10 | C23: Plate 24 mm ASTM A283 Gr.C | H23: 1 | I23: Kg | J23: 13361 | L23: =H23*J23 -> 13361
B24: 1.11 | C24: Plate 26 mm ASTM A283 Gr.C | H24: 1 | I24: Kg | J24: 13361 | L24: =H24*J24 -> 13361
B25: 1.12 | C25: Plate 28 mm ASTM A283 Gr.C | H25: 1 | I25: Kg | J25: 13361 | L25: =H25*J25 -> 13361
... B30: 1.17 | C30: Plate 38 mm ASTM A283 Gr.C | H30: 1 | I30: Kg | J30: 12780 | L30: =H30*J30 -> 12780
B31: 2 | C31: Steel Plate ASTM A36
B32: 2.1 | C32: Plate 6 mm ASTM A36 | H32: 1 | I32: Kg | J32: 13728 | L32: =H32*J32 -> 13728
B33: 2.2 | C33: Plate 8 mm ASTM A36 | H33: 1 | I33: Kg | J33: 12603 | L33: =H33*J33 -> 12603
B34: 2.3 | C34: Plate 10 mm ASTM A36 | H34: 1 | I34: Kg | J34: 12603 | L34: =H34*J34 -> 12603
B35: 2.4 | C35: Plate 12 mm ASTM A36 | H35: 1 | I35: Kg | J35: 12570 | L35: =H35*J35 -> 12570
B36: 2.5 | C36: Plate 14 mm ASTM A36 | H36: 1 | I36: Kg | J36: 12570 | L36: =H36*J36 -> 12570
B37: 2.6 | C37: Plate 16 mm ASTM A36 | H37: 1 | I37: Kg | J37: 12605 | L37: =H37*J37 -> 12605
B38: 2.7 | C38: Plate 18 mm ASTM A36 | H38: 1 | I38: Kg | J38: 12605 | L38: =H38*J38 -> 12605
B39: 2.8 | C39: Plate 20 mm ASTM A36 | H39: 1 | I39: Kg | J39: 12605 | L39: =H39*J39 -> 12605
B40: 2.9 | C40: Plate 22 mm ASTM A36 | H40: 1 | I40: Kg | J40: 12605 | L40: =H40*J40 -> 12605
B41: 2.10 | C41: Plate 24 mm ASTM A36 | H41: 1 | I41: Kg | J41: 12605 | L41: =H41*J41 -> 12605
B42: 2.11 | C42: Plate 26 mm ASTM A36 | H42: 1 | I42: Kg | J42: 12605 | L42: =H42*J42 -> 12605
B43: 2.12 | C43: Plate 28 mm ASTM A36 | H43: 1 | I43: Kg | J43: 12605 | L43: =H43*J43 -> 12605
... B48: 2.17 | C48: Plate 38 mm ASTM A36 | H48: 1 | I48: Kg | J48: 12210 | L48: =H48*J48 -> 12210
B52: II | C52: PIPA CARBON STEEL - ERW
B53: 1 | C53: Steel Pipe ERW API 5L Grade B Sch 40
B54: 1.4 | C54: Pipa API 5L grade B Ø 2" Sch. 40 | H54: 1 | I54: m | J54: 188610 | L54: =H54*J54 -> 188610
B55: 1.5 | C55: Pipa API 5L grade B Ø 2,5" Sch. 40 | H55: 1 | I55: m | J55: 302100 | L55: =H55*J55 -> 302100
...
