Workbook

Sheet Phisical Check
A1: RAB RPD 03 Cleaning Tangki 4,3,2,1 AFT A Yani (Updated Final Version)
A2: BILL OF QUANTITY
A3: PEKERJAAN | E3: : | F3: CLEANING TANGKI PENDAM T3, T4, T2, DAN T1
A4: LOKASI | E4: : | F4: AFT A Yani
A6: No | B6: URAIAN PEKERJAAN | J6: Satuan | K6: VOLUME | O6: KETERANGAN | T6: Start MPL | U6: 45499
K7: KONTRAK | M7: PELAKSANAAN | O7: SELISIH +/- | T7: MPL | U7: 210
K8: MATERIAL | L8: JASA | M8: MATERIAL | N8: JASA | O8: MATERIAL | P8: JASA | T8: bulan berjalan | U8: 45529
A9: I | B9: PEKERJAAN PERSIAPAN | U9: =U8-U6
B10: A | C10: PEKERJAAN PERSIAPAN | T10: persentase | U10: =U9/U7
C11: a.1 | D11: Direksi Kit Kelas 3 | J11: m2 | L11: 9 | O11: =M11-K11 | P11: =N11-L11 | Q11: =IF(K11=0,0,IF(M11/K11<1,M11/K11,100%)) | R11: =IF(L11=0,0,IF(N11/L11<1,N11/L11,100%))
B12: B | C12: PERALATAN PENDUKUNG
C13: b.1 | D13: Sewa Blower Explossion Proof Portable | J13: UD | L13: 20 | O13: =M13-K13 | P13: =N13-L13 | Q13: =IF(K13=0,0,IF(M13/K13<1,M13/K13,100%)) | R13: =IF(L13=0,0,IF(N13/L13<1,N13/L13,100%))
C14: b.2 | D14: Sewa Gas Tester | J14: UD | L14: 20 | O14: =M14-K14 | P14: =N14-L14 | Q14: =IF(K14=0,0,IF(M14/K14<1,M14/K14,100%)) | R14: =IF(L14=0,0,IF(N14/L14<1,N14/L14,100%))
C15: b.3 | D15: Sewa Apar Powder 9 Kg | J15: UD | L15: 40 | O15: =M15-K15 | P15: =N15-L15 | Q15: =IF(K15=0,0,IF(M15/K15<1,M15/K15,100%)) | R15: =IF(L15=0,0,IF(N15/L15<1,N15/L15,100%))
C16: b.4 | D16: Sewa Kompresor | J16: UD | L16: 12 | O16: =M16-K16 | P16: =N16-L16 | Q16: =IF(K16=0,0,IF(M16/K16<1,M16/K16,100%)) | R16: =IF(L16=0,0,IF(N16/L16<1,N16/L16,100%))
I17: Total I | M17: 0 | N17: =SUM(N10:N16) | O17: =M17/[1]rekap!$I$17 | P17: =N17/[1]rekap!$J$17
A18: II | B18: PEKERJAAN ENGINEERING DAN PROJECT MANAGEMENT
B19: A | C19: Pemenuhan Dokumen Project & Engineering
C20: a.1 | D20: Laporan Teknis dan HSSE Bulanan (1 set/project) | J20: set | L20: 1 | O20: =M20-K20 | P20: =N20-L20 | Q20: =IF(K20=0,0,IF(M20/K20<1,M20/K20,100%)) | R20: =IF(L20=0,0,IF(N20/L20<1,N20/L20,100%))
C21: a.2 | D21: MCU personil | J21: org | L21: 5 | O21: =M21-K21 | P21: =N21-L21 | Q21: =IF(K21=0,0,IF(M21/K21<1,M21/K21,100%)) | R21: =IF(L21=0,0,IF(N21/L21<1,N21/L21,100%))
C22: a.3 | D22: Inspection Report | J22: set | L22: 1 | O22: =M22-K22 | P22: =N22-L22 | Q22: =IF(K22=0,0,IF(M22/K22<1,M22/K22,100%)) | R22: =IF(L22=0,0,IF(N22/L22<1,N22/L22,100%))
B23: B | C23: Project Management (Kualifikasi dan Jumlah Personil sesuai dengan Kriteria Evaluasi Teknis dalam RKS)
C24: b.1 | D24: Safetyman | J24: MD | L24: 40 | O24: =M24-K24 | P24: =N24-L24 | Q24: =IF(K24=0,0,IF(M24/K24<1,M24/K24,100%)) | R24: =IF(L24=0,0,IF(N24/L24<1,N24/L24,100%))
I25: Total II | M25: =SUM(M18:M24) | N25: =SUM(N18:N24) | O25: =M25/[1]rekap!$I$17 | P25: =N25/[1]rekap!$J$17
A26: III | B26: CLEANING TANGKI TIMBUN
B27: A | C27: JASA
C28: b.1 | D28: Pekerjaan Free Gas Tangki Timbun incl report | J28: Day | L28: 8 | O28: =M28-K28 | P28: =N28-L28 | Q28: =IF(K28=0,0,IF(M28/K28<1,M28/K28,100%)) | R28: =IF(L28=0,0,IF(N28/L28<1,N28/L28,100%))
C29: b.2 | D29: Drain Produk Isi Pipa Avtur / Pertalite / Pertamax / Px.Turbo / Solar / Fame / Dex / Dexlite dan lainnya selain MDO/MFO | J29: liter | L29: 11975 | O29: =M29-K29 | P29: =N29-L29 | Q29: =IF(K29=0,0,IF(M29/K29<1,M29/K29,100%)) | R29: =IF(L29=0,0,IF(N29/L29<1,N29/L29,100%))
C30: b.3 | D30: Pemindahan drum isi produk ex drain ke sumptank | J30: liter | L30: 11975 | O30: =M30-K30 | P30: =N30-L30 | Q30: =IF(K30=0,0,IF(M30/K30<1,M30/K30,100%)) | R30: =IF(L30=0,0,IF(N30/L30<1,N30/L30,100%))
C31: b.4 | D31: Pencucian tangki timbun (diluar material air, solven dan sabun) | J31: m² | L31: 378.72025 | O31: =M31-K31 | P31: =N31-L31 | Q31: =IF(K31=0,0,IF(M31/K31<1,M31/K31,100%)) | R31: =IF(L31=0,0,IF(N31/L31<1,N31/L31,100%))
I32: Total III | M32: =SUM(M26:M31) | N32: =SUM(N26:N31) | O32: =M32/[1]rekap!$I$17 | P32: =N32/[1]rekap!$J$17
A33: IV | B33: PEKERJAAN ACCESORIS TANGKI
B34: A | C34: MATERIAL
C35: a.1 | D35: Gasket Spiral Wound #150 SS316L 4" | J35: pc | K35: 24 | O35: =M35-K35 | P35: =N35-L35 | Q35: =IF(K35=0,0,IF(M35/K35<1,M35/K35,100%)) | R35: =IF(L35=0,0,IF(N35/L35<1,N35/L35,100%))
C36: a.2 | D36: Packing Klingerit 1000 5mmx2mx1,5m | J36: lembar | K36: 4 | O36: =M36-K36 | P36: =N36-L36 | Q36: =IF(K36=0,0,IF(M36/K36<1,M36/K36,100%)) | R36: =IF(L36=0,0,IF(N36/L36<1,N36/L36,100%))
B37: B | C37: JASA
C38: a.1 | D38: Pembongkaran 2 Flange Accessories #150 (GV, BV, Check Valve, Flexible Pipe, Spool etc)
D39: a.1.1 | E39: Pembongkaran 2 Flange Accessories ø4" | J39: Unit | L39: 24 | O39: =M39-K39 | P39: =N39-L39 | Q39: =IF(K39=0,0,IF(M39/K39<1,M39/K39,100%)) | R39: =IF(L39=0,0,IF(N39/L39<1,N39/L39,100%))
C40: a.2 | D40: Penyetelan dan Pemasangan 2 Flange Accessories #150 (GV, BV, Check Valve, Flexible Pipe, Spool etc)
D41: a.2.1 | E41: Penyetelan dan Pemasangan 2 Flange Accessories ø4" | J41: Unit | L41: 24 | O41: =M41-K41 | P41: =N41-L41 | Q41: =IF(K41=0,0,IF(M41/K41<1,M41/K41,100%)) | R41: =IF(L41=0,0,IF(N41/L41<1,N41/L41,100%))
...

Sheet RPD03
B2: LAPORAN KEMAJUAN PEKERJAAN
B5: Periode | D5: : | E5: Agustus 2025
B6: Nama Proyek | D6: : | E6: CLEANING TANGKI PENDAM T3, T4, T2, DAN T1
B7: No. Kontrak | D7: : | E7: 3700018379, Tanggal 14 Agustus 2025
B8: Jangka Waktu | D8: : | E8: 120 (SERATUS DUA PULUH) HARI KALENDER
M9: FORM : RPD 03
B10: NO | C10: PERINCIAN PEKERJAAN | K10: Bobot thd Kontrak (%) | L10: Prestasi Total Tiap Jenis (%) | M10: Prestasi thd Kontra (%)
B13: I | C13: ='Phisical Check'!B9 | K13: 15.524207 | L13: ='03A-1'!M22 | M13: =K13*L13%
B15: II | C15: ='Phisical Check'!B18 | K15: 16.082485 | L15: ='03A-2'!M21 | M15: =K15*L15%
B17: III | C17: ='Phisical Check'!B26 | K17: 14.439913 | L17: ='03A-3'!M20 | M17: =K17*L17%
B19: IV | C19: ='Phisical Check'!B33 | K19: 26.085645 | L19: ='03A-4'!M28 | M19: =K19*L19%
B21: V | C21: ='Phisical Check'!B47 | K21: 0.88462881 | L21: ='03A-5'!M18 | M21: =K21*L21%
B23: VI | C23: ='Phisical Check'!B51 | K23: 26.983121 | L23: ='03A-6'!M18 | M23: =K23*L23%
B25: JUMLAH | K25: =SUM(K13:K24) | M25: =SUM(M12:M24)
K27: Cilacap,
C28: Mengetahui : | K28: Dibuat Oleh
C29: PT. PERTAMINA PATRA NIAGA | K29: PT. PERTAMINA MAINTENANCE AND CONSTRUCTION
C36: M. IRSAN | K36: RIKKI ANDARFIYAN SAPUTRA
C37: Region Manager RPD JBT | K37: Project Manager

Sheet 03A-1
A2: RINCIAN PRESTASI PEKERJAAN
A4: Nama Pekerjaan | E4: : | F4: =+'RPD03'!E6
A5: Periode | E5: : | F5: ='RPD03'!E5
A6: No. Kontrak | E6: : | F6: =+'RPD03'!E7
A7: Jangka Waktu | E7: : | F7: =+'RPD03'!E8
A8: Jenis Pekerjaan | E8: : | F8: =B14
A9: Bobot THD Kontrak | E9: : | F9: ='RPD03'!K13 | G9: %
A11: No | B11: PERINCIAN PEKERJAAN | I11: BOBOT MATERIAL (%) | J11: PRESTASI MATERIAL (%) | K11: BOBOT JASA (%) | L11: PRESTASI JASA (%) | M11: PRESTASI TOTAL (%)
A14: I | B14: ='Phisical Check'!B9
B15: ='Phisical Check'!B10 | C15: ='Phisical Check'!C10
C16: ='Phisical Check'!C11 | D16: ='Phisical Check'!D11 | K16: 68.508379 | L16: ='Phisical Check'!R11 | M16: =((I16*J16%)+(K16*L16%))*100
B17: ='Phisical Check'!B12 | C17: ='Phisical Check'!C12
C18: ='Phisical Check'!C13 | D18: ='Phisical Check'!D13 | K18: 1.9663132 | L18: ='Phisical Check'!R13 | M18: =((I18*J18%)+(K18*L18%))*100
C19: ='Phisical Check'!C14 | D19: ='Phisical Check'!D14 | K19: 11.728521 | L19: ='Phisical Check'!R14 | M19: =((I19*J19%)+(K19*L19%))*100
C20: ='Phisical Check'!C15 | D20: ='Phisical Check'!D15 | K20: 0.84091286 | L20: ='Phisical Check'!R15 | M20: =((I20*J20%)+(K20*L20%))*100
C21: ='Phisical Check'!C16 | D21: ='Phisical Check'!D16 | K21: 16.955874 | L21: ='Phisical Check'!R16 | M21: =((I21*J21%)+(K21*L21%))*100
B22: JUMLAH | M22: =SUM(M14:M21)
B25: Disetujui : | I25: ='RPD03'!K27
B26: ='RPD03'!C29 | I26: ='RPD03'!K29
B33: RISMAN EKO PRASETYO | I33: ='RPD03'!K36
B34: Ast Man Construction RPD JBT | I34: ='RPD03'!K37

Sheet 03A-2
A2: RINCIAN PRESTASI PEKERJAAN
A4: Nama Pekerjaan | E4: : | F4: =+'RPD03'!E6
A5: Periode | E5: : | F5: =+'03A-1'!F5
A6: No. Kontrak | E6: : | F6: =+'RPD03'!E7
A7: Jangka Waktu | E7: : | F7: =+'RPD03'!E8
A8: Jenis Pekerjaan | E8: : | F8: =B14
A9: Bobot THD Kontrak | E9: : | F9: ='RPD03'!K15 | G9: %
A11: No | B11: PERINCIAN PEKERJAAN | I11: BOBOT MATERIAL (%) | J11: PRESTASI MATERIAL (%) | K11: BOBOT JASA (%) | L11: PRESTASI JASA (%) | M11: PRESTASI TOTAL (%)
A14: II | B14: ='Phisical Check'!B18
B15: A | C15: Pemenuhan Dokumen Project & Engineering
C16: a.1 | D16: Laporan Teknis dan HSSE Bulanan (1 set/project) | K16: 6.2581356 | L16: ='Phisical Check'!R20 | M16: =((I16*J16%)+(K16*L16%))*100
C17: a.2 | D17: MCU personil | K17: 9.2854044 | L17: ='Phisical Check'!R21 | M17: =((I17*J17%)+(K17*L17%))*100
C18: a.3 | D18: Inspection Report | K18: 3.1290678 | L18: ='Phisical Check'!R22 | M18: =((I18*J18%)+(K18*L18%))*100
B19: B | C19: Project Management (Kualifikasi dan Jumlah Personil sesuai dengan Kriteria Evaluasi Teknis dalam RKS)
C20: b.1 | D20: Safetyman | K20: 81.327392 | L20: ='Phisical Check'!R24 | M20: =((I20*J20%)+(K20*L20%))*100
B21: JUMLAH | M21: =SUM(M15:M20)
I22: =SUM(I15:I20)
B24: Disetujui : | I24: ='03A-1'!$I$25
B25: ='03A-1'!B26 | I25: ='03A-1'!I26
B32: ='03A-1'!B33 | I32: ='03A-1'!I33
B33: ='03A-1'!B34 | I33: ='03A-1'!I34

Sheet 03A-3
A2: RINCIAN PRESTASI PEKERJAAN
A4: Nama Pekerjaan | E4: : | F4: =+'RPD03'!E6
A5: Periode | E5: : | F5: =+'03A-2'!F5
A6: No. Kontrak | E6: : | F6: =+'RPD03'!E7
A7: Jangka Waktu | E7: : | F7: =+'RPD03'!E8
A8: Jenis Pekerjaan | E8: : | F8: =B14
A9: Bobot THD Kontrak | E9: : | F9: ='RPD03'!K17 | G9: %
A11: No | B11: PERINCIAN PEKERJAAN | I11: BOBOT MATERIAL (%) | J11: PRESTASI MATERIAL (%) | K11: BOBOT JASA (%) | L11: PRESTASI JASA (%) | M11: PRESTASI TOTAL (%)
A14: ='Phisical Check'!A26 | B14: ='Phisical Check'!B26
B15: ='Phisical Check'!B27 | C15: ='Phisical Check'!C27
C16: ='Phisical Check'!C28 | D16: ='Phisical Check'!D28 | K16: 18.655135 | L16: ='Phisical Check'!R28 | M16: =((I16*J16%)+(K16*L16%))*100
C17: ='Phisical Check'!C29 | D17: ='Phisical Check'!D29 | K17: 25.76314 | L17: ='Phisical Check'!R29 | M17: =((I17*J17%)+(K17*L17%))*100
C18: ='Phisical Check'!C30 | D18: ='Phisical Check'!D30 | K18: 9.9046196 | L18: ='Phisical Check'!R30 | M18: =((I18*J18%)+(K18*L18%))*100
C19: ='Phisical Check'!C31 | D19: ='Phisical Check'!D31 | K19: 45.677105 | L19: ='Phisical Check'!R31 | M19: =((I19*J19%)+(K19*L19%))*100
B20: JUMLAH | M20: =SUM(M15:M19)
I21: =SUM(I16:I19) | K21: =SUM(K15:K19)
B22: Disetujui : | I22: ='03A-2'!$I$24
B23: ='03A-2'!B25 | I23: ='03A-2'!I25
B30: ='03A-2'!B32 | I30: ='03A-2'!I32
B31: ='03A-2'!B33 | I31: ='03A-2'!I33

Sheet 03A-4
A2: RINCIAN PRESTASI PEKERJAAN
A4: Nama Pekerjaan | E4: : | F4: =+'RPD03'!E6
A5: Periode | E5: : | F5: =+'03A-3'!F5
A6: No. Kontrak | E6: : | F6: =+'RPD03'!E7
A7: Jangka Waktu | E7: : | F7: =+'RPD03'!E8
A8: Jenis Pekerjaan | E8: : | F8: =B14
A9: Bobot THD Kontrak | E9: : | F9: ='RPD03'!K19 | G9: %
A11: No | B11: PERINCIAN PEKERJAAN | I11: BOBOT MATERIAL (%) | J11: PRESTASI MATERIAL (%) | K11: BOBOT JASA (%) | L11: PRESTASI JASA (%) | M11: PRESTASI TOTAL (%)
A14: ='Phisical Check'!A33 | B14: ='Phisical Check'!B33
B15: ='Phisical Check'!B34 | C15: ='Phisical Check'!C34
C16: ='Phisical Check'!C35 | D16: ='Phisical Check'!D35 | I16: 18.003159 | J16: ='Phisical Check'!Q35 | M16: =((I16*J16%)+(K16*L16%))*100
C17: ='Phisical Check'!C36 | D17: ='Phisical Check'!D36 | I17: 62.684286 | J17: ='Phisical Check'!Q36 | M17: =((I17*J17%)+(K17*L17%))*100
B18: ='Phisical Check'!B37 | C18: ='Phisical Check'!C37
C19: ='Phisical Check'!C38 | D19: ='Phisical Check'!D38
D20: ='Phisical Check'!D39 | E20: ='Phisical Check'!E39 | K20: 2.6041398 | L20: ='Phisical Check'!R39 | M20: =((I20*J20%)+(K20*L20%))*100
C21: ='Phisical Check'!C40 | D21: ='Phisical Check'!D40
D22: ='Phisical Check'!D41 | E22: ='Phisical Check'!E41 | K22: 8.561733 | L22: ='Phisical Check'!R41 | M22: =((I22*J22%)+(K22*L22%))*100
C23: ='Phisical Check'!C42 | D23: ='Phisical Check'!D42
D24: ='Phisical Check'!D43 | E24: ='Phisical Check'!E43 | K24: 3.7595323 | L24: ='Phisical Check'!R43 | M24: =((I24*J24%)+(K24*L24%))*100
C25: ='Phisical Check'!C44 | D25: ='Phisical Check'!D44
D26: ='Phisical Check'!D45 | E26: ='Phisical Check'!E45 | K26: 4.3871499 | L26: ='Phisical Check'!R45 | M26: =((I26*J26%)+(K26*L26%))*100
B28: JUMLAH | M28: =SUM(M15:M27)
B31: Disetujui : | J31: ='03A-3'!$I$22
B32: ='03A-3'!B23 | J32: ='03A-3'!I23
B39: ='03A-3'!B30 | J39: ='03A-3'!I30
B40: ='03A-3'!B31 | J40: ='03A-3'!I31

Sheet 03A-5
A2: RINCIAN PRESTASI PEKERJAAN
A4: Nama Pekerjaan | E4: : | F4: =+'RPD03'!E6
A5: Periode | E5: : | F5: =+'03A-3'!F5
A6: No. Kontrak | E6: : | F6: =+'RPD03'!E7
A7: Jangka Waktu | E7: : | F7: =+'RPD03'!E8
A8: Jenis Pekerjaan | E8: : | F8: =B14
A9: Bobot THD Kontrak | E9: : | F9: ='RPD03'!K21 | G9: %
A11: No | B11: PERINCIAN PEKERJAAN | I11: BOBOT MATERIAL (%) | J11: PRESTASI MATERIAL (%) | K11: BOBOT JASA (%) | L11: PRESTASI JASA (%) | M11: PRESTASI TOTAL (%)
A14: ='Phisical Check'!A47 | B14: ='Phisical Check'!B47
B15: ='Phisical Check'!B48 | C15: ='Phisical Check'!C48
C16: ='Phisical Check'!C49 | D16: ='Phisical Check'!D49 | I16: 37.496248 | J16: ='Phisical Check'!Q49 | K16: 62.503752 | L16: ='Phisical Check'!R49 | M16: =((I16*J16%)+(K16*L16%))*100
B18: JUMLAH | M18: =SUM(M14:M17)
B20: Disetujui : | J20: ='03A-4'!$J$31
B21: ='03A-4'!B32 | J21: ='03A-3'!I23
B28: ='03A-3'!B30 | J28: ='03A-3'!I30
B29: ='03A-3'!B31 | J29: ='03A-3'!I31

Sheet 03A-6
A2: RINCIAN PRESTASI PEKERJAAN
A4: Nama Pekerjaan | E4: : | F4: =+'RPD03'!E6
A5: Periode | E5: : | F5: =+'03A-3'!F5
A6: No. Kontrak | E6: : | F6: =+'RPD03'!E7
A7: Jangka Waktu | E7: : | F7: =+'RPD03'!E8
A8: Jenis Pekerjaan | E8: : | F8: =B14
A9: Bobot THD Kontrak | E9: : | F9: ='RPD03'!K23 | G9: %
A11: No | B11: PERINCIAN PEKERJAAN | I11: BOBOT MATERIAL (%) | J11: PRESTASI MATERIAL (%) | K11: BOBOT JASA (%) | L11: PRESTASI JASA (%) | M11: PRESTASI TOTAL (%)
A14: ='Phisical Check'!A51 | B14: ='Phisical Check'!B51
B15: ='Phisical Check'!B52 | C15: ='Phisical Check'!C52 | K15: 16.614205 | L15: ='Phisical Check'!R52 | M15: =((I15*J15%)+(K15*L15%))*100
B16: ='Phisical Check'!B53 | C16: ='Phisical Check'!C53 | K16: 5.8023098 | L16: ='Phisical Check'!R53 | M16: =((I16*J16%)+(K16*L16%))*100
B17: ='Phisical Check'!B54 | C17: ='Phisical Check'!C54 | K17: 77.583485 | L17: ='Phisical Check'!R54 | M17: =((I17*J17%)+(K17*L17%))*100
B18: JUMLAH | M18: =SUM(M15:M17)
B20: Disetujui : | J20: ='03A-5'!$J$20
B21: ='03A-4'!B32 | J21: ='03A-3'!I23
B28: ='03A-3'!B30 | J28: ='03A-3'!I30
B29: ='03A-3'!B31 | J29: ='03A-3'!I31

Sheet kurva S
A3: TIME SCHEDULLE
A5: =[2]BOQ!A3 | F5: : | G5: =[2]BOQ!E3
A6: =[2]BOQ!A4 | F6: : | G6: =[2]BOQ!E4
A7: Jangka Waktu | F7: : | G7: 120 (Seratus Dua Puluh) hari kalender
A9: NO | B9: URAIAN PEKERJAAN | H9: BOBOT % | I9: KET. | J9: 45870 | N9: 45901 | R9: 45931 | W9: 45962 | AB9: VALUE SCALE
J10: MINGGU KE - | N10: MINGGU KE - | R10: MINGGU KE - | W10: MINGGU KE -
J11: 1 | K11: 2 | L11: 3 | M11: 4 | N11: 5 | O11: 6 | P11: 7 | Q11: 8 | R11: 9 | S11: 10 | T11: 11 | U11: 12 | V11: 13 | W11: 14 | X11: 15 | Y11: 16 | Z11: 17 | AA11: 18
J12: 31 jul-6 ags | K12: 7-13 ags | L12: 14-20 ags | M12: 21-27 ags | N12: 28 ags-3 sep | O12: 4-10 sep | P12: 11-17 sep | Q12: 18-24 sep | R12: 25 sep-1 okt | S12: 2-8 okt | T12: 9-15 okt | U12: 16-22 okt | V12: 23-29 okt | W12: 30 okt-5 nov | X12: 6-12 nov | Y12: 13-19 nov | Z12: 20-26 nov | AA12: 27 nov-3 des
A14: I | B14: PEKERJAAN PERSIAPAN
A15: A | B15: PEKERJAAN PERSIAPAN
B16: a.1 | C16: Direksi Kit Kelas 3 | H16: 10.635383 | I16: RENCANA | Q16: =H16/11 | R16: =Q16 | S16: =R16 | T16: =S16 | U16: =T16 | V16: =U16 | W16: =V16 | X16: =W16 | Y16: =X16 | ... AA16: =Z16
A17: B | B17: PERALATAN PENDUKUNG
B18: b.1 | C18: Sewa Blower Explossion Proof Portable | H18: 0.30525454 | I18: RENCANA | R18: =H18/5 | S18: =R18 | T18: =S18 | U18: =T18 | V18: =U18
B19: b.2 | C19: Sewa Gas Tester | H19: 1.82076 | I19: RENCANA | Q19: =H19/7 | R19: =Q19 | S19: =R19 | T19: =S19 | U19: =T19 | V19: =U19 | W19: =V19
B20: b.3 | C20: Sewa Apar Powder 9 Kg | H20: 0.13054505 | I20: RENCANA | Q20: =H20/7 | R20: =Q20 | S20: =R20 | T20: =S20 | U20: =T20 | V20: =U20 | W20: =V20
B21: b.4 | C21: Sewa Kompresor | H21: 2.632265 | I21: RENCANA | R21: =H21/6 | S21: =R21 | T21: =S21 | U21: =T21 | V21: =U21 | W21: =V21
A23: II | B23: PEKERJAAN ENGINEERING DAN PROJECT MANAGEMENT
A24: A | B24: Pemenuhan Dokumen Project & Engineering
B25: a.1 | C25: Laporan Teknis dan HSSE Bulanan (1 set/project) | H25: 1.0064637 | I25: RENCANA | M25: =H25/4 | Q25: =M25 | V25: =Q25 | AA25: =V25
B26: a.2 | C26: MCU personil | H26: 1.4933238 | I26: RENCANA | M26: =H26/4 | N26: =M26 | O26: =N26 | P26: =O26
B27: a.3 | C27: Inspection Report | H27: 0.50323186 | I27: RENCANA | Z27: =H27
A28: B | B28: Project Management (Kualifikasi dan Jumlah Personil sesuai dengan Kriteria Evaluasi Teknis dalam RKS) | I28: RENCANA
B29: b.1 | C29: Safetyman | H29: 13.079466 | Q29: =H29/11 | R29: =Q29 | S29: =R29 | T29: =S29 | U29: =T29 | V29: =U29 | W29: =V29 | X29: =W29 | Y29: =X29 | ... AA29: =Z29
B31: INFO TANK CLEANNING TANGKI PENDAM NO. 03, 04, 02 & 01 ( AVTUR )
B32: Kapasitas Tangki (KL) | G32: : 50 KL
B33: Dia. X Tinggi Tangki (M) | G33: : 9,2 x 2,7 M
A35: III | B35: CLEANING TANGKI TIMBUN
A36: A | B36: JASA
B37: b.1 | C37: Pekerjaan Free Gas Tangki Timbun incl report | H37: 2.6937854 | I37: RENCANA | Q37: =H37/5 | R37: =Q37 | S37: =Q37 | U37: =S37 | W37: =U37
B38: b.2 | C38: Drain Produk Isi Pipa Avtur / Pertalite / Pertamax / Px.Turbo / Solar / Fame / Dex / Dexlite dan lainnya selain MDO/MFO | H38: 3.7201751 | I38: RENCANA | R38: =H38/4 | S38: =R38 | U38: =S38 | W38: =U38
B39: b.3 | C39: Pemindahan drum isi produk ex drain ke sumptank | H39: 1.4302185 | I39: RENCANA | R39: =H39/4 | T39: =R39 | V39: =T39 | W39: =V39
B40: b.4 | C40: Pencucian tangki timbun (diluar material air, solven dan sabun) | H40: 6.5957344 | I40: RENCANA | R40: =H40/6 | S40: =R40 | T40: =S40 | U40: =T40 | V40: =U40 | W40: =V40
A42: IV | B42: PEKERJAAN ACCESORIS TANGKI
A43: A | B43: MATERIAL
B44: a.1 | C44: Gasket Spiral Wound #150 SS316L 4" | H44: 4.6962402 | I44: RENCANA | S44: =H44
B45: a.2 | C45: Packing Klingerit 1000 5mmx2mx1,5m | H45: 16.3516 | I45: RENCANA | S45: =H45/4 | U45: =S45 | W45: =U45 | Y45: =W45
A46: B | B46: JASA
B47: a.1 | C47: Pembongkaran 2 Flange Accessories #150 (GV, BV, Check Valve, Flexible Pipe, Spool etc) | H47: 0.67930665 | I47: RENCANA | S47: =H47/4 | U47: =S47 | W47: =U47 | Y47: =W47
C48: a.1.1 | D48: Pembongkaran 2 Flange Accessories ø4"
B49: a.2 | C49: Penyetelan dan Pemasangan 2 Flange Accessories #150 (GV, BV, Check Valve, Flexible Pipe, Spool etc) | H49: 2.2333833 | I49: RENCANA | T49: =H49/4 | V49: =T49 | X49: =V49 | Y49: =X49
...

Sheet AHSP Resmi
A1: AHSP Resmi (Updated ChatGPT-5)

Sheet TKDN & Pajak
A1: TKDN & Pajak (Updated ChatGPT-5)

Sheet Mobilisasi
A1: Mobilisasi (Updated ChatGPT-5)
